Workbook

Sheet Lisez-moi
A1: Hero's Draft — Les systèmes et leurs calculs
A2: Version du jeu : 0.5.5 (branche main, commit 0ec09ab, lue le 13/10/2026). Tout ce qui se calcule sans dé.
A4: Comment lire ce classeur
A5: Texte bleu | B5: Constante du code Dart ou valeur d'un fichier JSON de assets/data/. Modifiable pour tester un rééquilibrage.
A6: Texte bleu sur fond jaune | B6: Paramètre de scénario (acte, niveau du joueur, PV…) : à saisir.
A7: Texte noir | B7: Formule.
A8: Texte vert | B8: Lien vers un autre onglet.
A9: Ligne « Source » | B9: Fichier et fonction du dépôt où vit la règle, relus le 13/10/2026.
A11: Les onglets
A12: Onglet | B12: Contenu
A13: Difficulté par acte | B13: Escalier géométrique des PV et dégâts ennemis, niveau d'ennemi, tiers, budgets de menace, de l'acte 1 à 20.
A14: Ennemis par acte | B14: PV, dégâts et note de menace de chaque ennemi, acte par acte, pour un type de nœud choisi.
A15: Calculateur de combat | B15: Un combat précis : puissance du joueur, budget, multiplicateurs, chaque ennemi, XP et or qu'il rapporte.
A16: Courbe d'XP | B16: Prix d'un niveau par acte, XP par ennemi selon son niveau, kills nécessaires, progression cumulée.
A17: Économie (or) | B17: Or de départ, or par ennemi, prix de la boutique, affûtage, Puits, événements, Colporteur, budget d'un acte.
A18: Cartes & rareté | B18: Règle G1 (×1,2 / 1,4 / 1,6 / 2,0, au moins +1 par palier), les 23 cartes à chaque rareté, coût en copies des fusions.
A19: Runes (valeurs) | B19: Bonus en pourcentage (au moins +niveau), runes élémentaires, Précis, plafonds, coût d'affûtage cumulé, Puits.
A20: Dégâts & statuts | B20: Pipeline de dégâts, attaque effective d'un ennemi, armure, poison et brûlure sur la durée, conversion du Berserker.
A21: Passifs & Maîtrise | B21: Les neuf passifs avec la Maîtrise appliquée, tables selon les PV manquants, l'armure survivante, le mana restant.
A22: Héros & récompenses | B22: Statistiques de départ, valeurs des récompenses de niveau et leur espérance, reliques, soins.
A23: Main & pioche | B23: Cadence de la pioche et du remélange selon la taille du deck.
A25: Les tirages aléatoires (raretés, trouvaille, carte du monde, runes…) sont dans 2026-10-13_probabilites_du_jeu.xlsx.

Sheet Difficulté par acte
A1: Difficulté par acte
A2: EncounterSystem (lib/game/systems/encounter_system.dart) — ADR-070 / ADR-072 : l'acte n'entre que dans le facteur d'escalier, jamais dans le niveau d'ennemi
A4: Constantes
A5: Taux PV par palier | B5: 1.35 | C5: _hpBracketGrowthRate
A6: Taux dégâts par palier | B6: 1.25 | C6: _dmgBracketGrowthRate
A7: Rampe PV intra-palier | B7: 0.05 | C7: _hpIntraBracketStep
A8: Rampe dégâts intra-palier | B8: 0.03 | C8: _dmgIntraBracketStep
A9: Taille d'un palier (actes) | B9: 2 | C9: _actBracketSize
A10: Déblocage de tier (actes) | B10: 5 | C10: _tierUnlockBracketSize
A11: PV : + par niveau d'ennemi | B11: 0.06 | C11: getHpMultiplier
A12: Dégâts : + par niveau d'ennemi | B12: 0.04 | C12: getDamageMultiplier
A13: Niveaux gagnés par acte (scénario) | B13: 2 | C13: cible de la courbe d'XP (D24)
A15: Acte | B15: Palier | C15: Position | D15: Facteur PV | E15: Facteur dégâts | F15: Tier max | G15: Max normal | H15: Max élite | I15: Max boss | J15: Niveau joueur (début d'acte) | K15: Niveau ennemi normal | L15: Niveau élite | M15: Niveau boss | N15: × PV normal | O15: × dégâts normal | P15: × PV élite | Q15: × dégâts élite | R15: × PV boss | S15: × dégâts boss
A16: 1 | B16: =INT((A16-1)/$B$9) -> 0 | C16: =MOD(A16-1,$B$9) -> 0 | D16: =$B$5^B16*(1+$B$7*C16) -> 1 | E16: =$B$6^B16*(1+$B$8*C16) -> 1 | F16: =MIN(3,1+INT((A16-1)/$B$10)) -> 1 | G16: =A16 -> 1 | H16: =1+INT((A16-1)/2) -> 1 | I16: =1+INT((A16-1)/5) -> 1 | J16: =1+$B$13*(A16-1) -> 1 | K16: =J16 -> 1 | L16: =J16+1 -> 2 | M16: =J16+2 -> 3 | N16: =(1+$B$11*(K16-1))*D16 -> 1 | O16: =(1+$B$12*(K16-1))*E16 -> 1 | P16: =(1+$B$11*(L16-1))*D16*1.5 -> 1.59 | Q16: =(1+$B$12*(L16-1))*E16*1.5 -> 1.56 | R16: =(1+$B$11*(M16-1))*D16*3 -> 3.36 | S16: =(1+$B$12*(M16-1))*E16*3 -> 3.24
A17: 2 | B17: =INT((A17-1)/$B$9) -> 0 | C17: =MOD(A17-1,$B$9) -> 1 | D17: =$B$5^B17*(1+$B$7*C17) -> 1.05 | E17: =$B$6^B17*(1+$B$8*C17) -> 1.03 | F17: =MIN(3,1+INT((A17-1)/$B$10)) -> 1 | G17: =A17 -> 2 | H17: =1+INT((A17-1)/2) -> 1 | I17: =1+INT((A17-1)/5) -> 1 | J17: =1+$B$13*(A17-1) -> 3 | K17: =J17 -> 3 | L17: =J17+1 -> 4 | M17: =J17+2 -> 5 | N17: =(1+$B$11*(K17-1))*D17 -> 1.176 | O17: =(1+$B$12*(K17-1))*E17 -> 1.1124 | P17: =(1+$B$11*(L17-1))*D17*1.5 -> 1.8585 | Q17: =(1+$B$12*(L17-1))*E17*1.5 -> 1.7304 | R17: =(1+$B$11*(M17-1))*D17*3 -> 3.906 | S17: =(1+$B$12*(M17-1))*E17*3 -> 3.5844
A18: 3 | B18: =INT((A18-1)/$B$9) -> 1 | C18: =MOD(A18-1,$B$9) -> 0 | D18: =$B$5^B18*(1+$B$7*C18) -> 1.35 | E18: =$B$6^B18*(1+$B$8*C18) -> 1.25 | F18: =MIN(3,1+INT((A18-1)/$B$10)) -> 1 | G18: =A18 -> 3 | H18: =1+INT((A18-1)/2) -> 2 | I18: =1+INT((A18-1)/5) -> 1 | J18: =1+$B$13*(A18-1) -> 5 | K18: =J18 -> 5 | L18: =J18+1 -> 6 | M18: =J18+2 -> 7 | N18: =(1+$B$11*(K18-1))*D18 -> 1.674 | O18: =(1+$B$12*(K18-1))*E18 -> 1.45 | P18: =(1+$B$11*(L18-1))*D18*1.5 -> 2.6325 | Q18: =(1+$B$12*(L18-1))*E18*1.5 -> 2.25 | R18: =(1+$B$11*(M18-1))*D18*3 -> 5.508 | S18: =(1+$B$12*(M18-1))*E18*3 -> 4.65
A19: 4 | B19: =INT((A19-1)/$B$9) -> 1 | C19: =MOD(A19-1,$B$9) -> 1 | D19: =$B$5^B19*(1+$B$7*C19) -> 1.4175 | E19: =$B$6^B19*(1+$B$8*C19) -> 1.2875 | F19: =MIN(3,1+INT((A19-1)/$B$10)) -> 1 | G19: =A19 -> 4 | H19: =1+INT((A19-1)/2) -> 2 | I19: =1+INT((A19-1)/5) -> 1 | J19: =1+$B$13*(A19-1) -> 7 | K19: =J19 -> 7 | L19: =J19+1 -> 8 | M19: =J19+2 -> 9 | N19: =(1+$B$11*(K19-1))*D19 -> 1.9278 | O19: =(1+$B$12*(K19-1))*E19 -> 1.5965 | P19: =(1+$B$11*(L19-1))*D19*1.5 -> 3.019275 | Q19: =(1+$B$12*(L19-1))*E19*1.5 -> 2.472 | R19: =(1+$B$11*(M19-1))*D19*3 -> 6.2937 | S19: =(1+$B$12*(M19-1))*E19*3 -> 5.0985
A20: 5 | B20: =INT((A20-1)/$B$9) -> 2 | C20: =MOD(A20-1,$B$9) -> 0 | D20: =$B$5^B20*(1+$B$7*C20) -> 1.8225 | E20: =$B$6^B20*(1+$B$8*C20) -> 1.5625 | F20: =MIN(3,1+INT((A20-1)/$B$10)) -> 1 | G20: =A20 -> 5 | H20: =1+INT((A20-1)/2) -> 3 | I20: =1+INT((A20-1)/5) -> 1 | J20: =1+$B$13*(A20-1) -> 9 | K20: =J20 -> 9 | L20: =J20+1 -> 10 | M20: =J20+2 -> 11 | N20: =(1+$B$11*(K20-1))*D20 -> 2.6973 | O20: =(1+$B$12*(K20-1))*E20 -> 2.0625 | P20: =(1+$B$11*(L20-1))*D20*1.5 -> 4.209975 | Q20: =(1+$B$12*(L20-1))*E20*1.5 -> 3.1875 | R20: =(1+$B$11*(M20-1))*D20*3 -> 8.748 | S20: =(1+$B$12*(M20-1))*E20*3 -> 6.5625
A21: 6 | B21: =INT((A21-1)/$B$9) -> 2 | C21: =MOD(A21-1,$B$9) -> 1 | D21: =$B$5^B21*(1+$B$7*C21) -> 1.913625 | E21: =$B$6^B21*(1+$B$8*C21) -> 1.609375 | F21: =MIN(3,1+INT((A21-1)/$B$10)) -> 2 | G21: =A21 -> 6 | H21: =1+INT((A21-1)/2) -> 3 | I21: =1+INT((A21-1)/5) -> 2 | J21: =1+$B$13*(A21-1) -> 11 | K21: =J21 -> 11 | L21: =J21+1 -> 12 | M21: =J21+2 -> 13 | N21: =(1+$B$11*(K21-1))*D21 -> 3.0618 | O21: =(1+$B$12*(K21-1))*E21 -> 2.253125 | P21: =(1+$B$11*(L21-1))*D21*1.5 -> 4.7649263 | Q21: =(1+$B$12*(L21-1))*E21*1.5 -> 3.47625 | R21: =(1+$B$11*(M21-1))*D21*3 -> 9.874305 | S21: =(1+$B$12*(M21-1))*E21*3 -> 7.145625
A22: 7 | B22: =INT((A22-1)/$B$9) -> 3 | C22: =MOD(A22-1,$B$9) -> 0 | D22: =$B$5^B22*(1+$B$7*C22) -> 2.460375 | E22: =$B$6^B22*(1+$B$8*C22) -> 1.953125 | F22: =MIN(3,1+INT((A22-1)/$B$10)) -> 2 | G22: =A22 -> 7 | H22: =1+INT((A22-1)/2) -> 4 | I22: =1+INT((A22-1)/5) -> 2 | J22: =1+$B$13*(A22-1) -> 13 | K22: =J22 -> 13 | L22: =J22+1 -> 14 | M22: =J22+2 -> 15 | N22: =(1+$B$11*(K22-1))*D22 -> 4.231845 | O22: =(1+$B$12*(K22-1))*E22 -> 2.890625 | P22: =(1+$B$11*(L22-1))*D22*1.5 -> 6.5692013 | Q22: =(1+$B$12*(L22-1))*E22*1.5 -> 4.453125 | R22: =(1+$B$11*(M22-1))*D22*3 -> 13.58127 | S22: =(1+$B$12*(M22-1))*E22*3 -> 9.140625
A23: 8 | B23: =INT((A23-1)/$B$9) -> 3 | C23: =MOD(A23-1,$B$9) -> 1 | D23: =$B$5^B23*(1+$B$7*C23) -> 2.5833938 | E23: =$B$6^B23*(1+$B$8*C23) -> 2.0117188 | F23: =MIN(3,1+INT((A23-1)/$B$10)) -> 2 | G23: =A23 -> 8 | H23: =1+INT((A23-1)/2) -> 4 | I23: =1+INT((A23-1)/5) -> 2 | J23: =1+$B$13*(A23-1) -> 15 | K23: =J23 -> 15 | L23: =J23+1 -> 16 | M23: =J23+2 -> 17 | N23: =(1+$B$11*(K23-1))*D23 -> 4.7534445 | O23: =(1+$B$12*(K23-1))*E23 -> 3.1382812 | P23: =(1+$B$11*(L23-1))*D23*1.5 -> 7.3626722 | Q23: =(1+$B$12*(L23-1))*E23*1.5 -> 4.828125 | R23: =(1+$B$11*(M23-1))*D23*3 -> 15.190355 | S23: =(1+$B$12*(M23-1))*E23*3 -> 9.8976563
A24: 9 | B24: =INT((A24-1)/$B$9) -> 4 | C24: =MOD(A24-1,$B$9) -> 0 | D24: =$B$5^B24*(1+$B$7*C24) -> 3.3215063 | E24: =$B$6^B24*(1+$B$8*C24) -> 2.4414062 | F24: =MIN(3,1+INT((A24-1)/$B$10)) -> 2 | G24: =A24 -> 9 | H24: =1+INT((A24-1)/2) -> 5 | I24: =1+INT((A24-1)/5) -> 2 | J24: =1+$B$13*(A24-1) -> 17 | K24: =J24 -> 17 | L24: =J24+1 -> 18 | M24: =J24+2 -> 19 | N24: =(1+$B$11*(K24-1))*D24 -> 6.5101523 | O24: =(1+$B$12*(K24-1))*E24 -> 4.0039062 | P24: =(1+$B$11*(L24-1))*D24*1.5 -> 10.064164 | Q24: =(1+$B$12*(L24-1))*E24*1.5 -> 6.1523438 | R24: =(1+$B$11*(M24-1))*D24*3 -> 20.726199 | S24: =(1+$B$12*(M24-1))*E24*3 -> 12.597656
A25: 10 | B25: =INT((A25-1)/$B$9) -> 4 | C25: =MOD(A25-1,$B$9) -> 1 | D25: =$B$5^B25*(1+$B$7*C25) -> 3.4875816 | E25: =$B$6^B25*(1+$B$8*C25) -> 2.5146484 | F25: =MIN(3,1+INT((A25-1)/$B$10)) -> 2 | G25: =A25 -> 10 | H25: =1+INT((A25-1)/2) -> 5 | I25: =1+INT((A25-1)/5) -> 2 | J25: =1+$B$13*(A25-1) -> 19 | K25: =J25 -> 19 | L25: =J25+1 -> 20 | M25: =J25+2 -> 21 | N25: =(1+$B$11*(K25-1))*D25 -> 7.2541697 | O25: =(1+$B$12*(K25-1))*E25 -> 4.3251953 | P25: =(1+$B$11*(L25-1))*D25*1.5 -> 11.195137 | Q25: =(1+$B$12*(L25-1))*E25*1.5 -> 6.6386719 | R25: =(1+$B$11*(M25-1))*D25*3 -> 23.018038 | S25: =(1+$B$12*(M25-1))*E25*3 -> 13.579102
A26: 11 | B26: =INT((A26-1)/$B$9) -> 5 | C26: =MOD(A26-1,$B$9) -> 0 | D26: =$B$5^B26*(1+$B$7*C26) -> 4.4840334 | E26: =$B$6^B26*(1+$B$8*C26) -> 3.0517578 | F26: =MIN(3,1+INT((A26-1)/$B$10)) -> 3 | G26: =A26 -> 11 | H26: =1+INT((A26-1)/2) -> 6 | I26: =1+INT((A26-1)/5) -> 3 | J26: =1+$B$13*(A26-1) -> 21 | K26: =J26 -> 21 | L26: =J26+1 -> 22 | M26: =J26+2 -> 23 | N26: =(1+$B$11*(K26-1))*D26 -> 9.8648736 | O26: =(1+$B$12*(K26-1))*E26 -> 5.4931641 | P26: =(1+$B$11*(L26-1))*D26*1.5 -> 15.200873 | Q26: =(1+$B$12*(L26-1))*E26*1.5 -> 8.4228516 | R26: =(1+$B$11*(M26-1))*D26*3 -> 31.208873 | S26: =(1+$B$12*(M26-1))*E26*3 -> 17.211914
A27: 12 | B27: =INT((A27-1)/$B$9) -> 5 | C27: =MOD(A27-1,$B$9) -> 1 | D27: =$B$5^B27*(1+$B$7*C27) -> 4.7082351 | E27: =$B$6^B27*(1+$B$8*C27) -> 3.1433105 | F27: =MIN(3,1+INT((A27-1)/$B$10)) -> 3 | G27: =A27 -> 12 | H27: =1+INT((A27-1)/2) -> 6 | I27: =1+INT((A27-1)/5) -> 3 | J27: =1+$B$13*(A27-1) -> 23 | K27: =J27 -> 23 | L27: =J27+1 -> 24 | M27: =J27+2 -> 25 | N27: =(1+$B$11*(K27-1))*D27 -> 10.923105 | O27: =(1+$B$12*(K27-1))*E27 -> 5.9094238 | P27: =(1+$B$11*(L27-1))*D27*1.5 -> 16.808399 | Q27: =(1+$B$12*(L27-1))*E27*1.5 -> 9.0527344 | R27: =(1+$B$11*(M27-1))*D27*3 -> 34.464281 | S27: =(1+$B$12*(M27-1))*E27*3 -> 18.482666
... A35: 20 | B35: =INT((A35-1)/$B$9) -> 9 | C35: =MOD(A35-1,$B$9) -> 1 | D35: =$B$5^B35*(1+$B$7*C35) -> 15.638432 | E35: =$B$6^B35*(1+$B$8*C35) -> 7.674098 | F35: =MIN(3,1+INT((A35-1)/$B$10)) -> 3 | G35: =A35 -> 20 | H35: =1+INT((A35-1)/2) -> 10 | I35: =1+INT((A35-1)/5) -> 4 | J35: =1+$B$13*(A35-1) -> 39 | K35: =J35 -> 39 | L35: =J35+1 -> 40 | M35: =J35+2 -> 41 | N35: =(1+$B$11*(K35-1))*D35 -> 51.294058 | O35: =(1+$B$12*(K35-1))*E35 -> 19.338727 | P35: =(1+$B$11*(L35-1))*D35*1.5 -> 78.348546 | Q35: =(1+$B$12*(L35-1))*E35*1.5 -> 29.468536 | R35: =(1+$B$11*(M35-1))*D35*3 -> 159.51201 | S35: =(1+$B$12*(M35-1))*E35*3 -> 59.857965
A36: Facteur PV à l'acte 25 : 1,35^12 ≈ 36,6 ; facteur dégâts ≈ 14,6 (ADR-072, voulu). Multiplicateurs de nœud : élite ×1,5, boss ×3 (PV comme dégâts) ; un boss « custom » (id boss_*) n'en a pas.
A38: Budget de menace à ratio de puissance 1 (joueur « dans les clous »)
A39: Source : calculateBudget : puissance attendue 145 + 15 (niv−1) + 20 (acte−1) ; budget de base 40 + 10 (niv−1) + 25 (acte−1) ; final = base × modificateur × nœud (1 / 1,5 / 2) + 10 (acte−1)
A40: Acte | B40: Niveau joueur | C40: Puissance attendue | D40: Budget de base | E40: Budget normal | F40: Budget élite | G40: Budget boss
A41: =A16 -> 1 | B41: =J16 -> 1 | C41: =145+(B41-1)*15+(A41-1)*20 -> 145 | D41: =40+(B41-1)*10+(A41-1)*25 -> 40 | E41: =D41+(A41-1)*10 -> 40 | F41: =D41*1.5+(A41-1)*10 -> 60 | G41: =D41*2+(A41-1)*10 -> 80
A42: =A17 -> 2 | B42: =J17 -> 3 | C42: =145+(B42-1)*15+(A42-1)*20 -> 195 | D42: =40+(B42-1)*10+(A42-1)*25 -> 85 | E42: =D42+(A42-1)*10 -> 95 | F42: =D42*1.5+(A42-1)*10 -> 137.5 | G42: =D42*2+(A42-1)*10 -> 180
A43: =A18 -> 3 | B43: =J18 -> 5 | C43: =145+(B43-1)*15+(A43-1)*20 -> 245 | D43: =40+(B43-1)*10+(A43-1)*25 -> 130 | E43: =D43+(A43-1)*10 -> 150 | F43: =D43*1.5+(A43-1)*10 -> 215 | G43: =D43*2+(A43-1)*10 -> 280
A44: =A19 -> 4 | B44: =J19 -> 7 | C44: =145+(B44-1)*15+(A44-1)*20 -> 295 | D44: =40+(B44-1)*10+(A44-1)*25 -> 175 | E44: =D44+(A44-1)*10 -> 205 | F44: =D44*1.5+(A44-1)*10 -> 292.5 | G44: =D44*2+(A44-1)*10 -> 380
A45: =A20 -> 5 | B45: =J20 -> 9 | C45: =145+(B45-1)*15+(A45-1)*20 -> 345 | D45: =40+(B45-1)*10+(A45-1)*25 -> 220 | E45: =D45+(A45-1)*10 -> 260 | F45: =D45*1.5+(A45-1)*10 -> 370 | G45: =D45*2+(A45-1)*10 -> 480
A46: =A21 -> 6 | B46: =J21 -> 11 | C46: =145+(B46-1)*15+(A46-1)*20 -> 395 | D46: =40+(B46-1)*10+(A46-1)*25 -> 265 | E46: =D46+(A46-1)*10 -> 315 | F46: =D46*1.5+(A46-1)*10 -> 447.5 | G46: =D46*2+(A46-1)*10 -> 580
A47: =A22 -> 7 | B47: =J22 -> 13 | C47: =145+(B47-1)*15+(A47-1)*20 -> 445 | D47: =40+(B47-1)*10+(A47-1)*25 -> 310 | E47: =D47+(A47-1)*10 -> 370 | F47: =D47*1.5+(A47-1)*10 -> 525 | G47: =D47*2+(A47-1)*10 -> 680
A48: =A23 -> 8 | B48: =J23 -> 15 | C48: =145+(B48-1)*15+(A48-1)*20 -> 495 | D48: =40+(B48-1)*10+(A48-1)*25 -> 355 | E48: =D48+(A48-1)*10 -> 425 | F48: =D48*1.5+(A48-1)*10 -> 602.5 | G48: =D48*2+(A48-1)*10 -> 780
A49: =A24 -> 9 | B49: =J24 -> 17 | C49: =145+(B49-1)*15+(A49-1)*20 -> 545 | D49: =40+(B49-1)*10+(A49-1)*25 -> 400 | E49: =D49+(A49-1)*10 -> 480 | F49: =D49*1.5+(A49-1)*10 -> 680 | G49: =D49*2+(A49-1)*10 -> 880
A50: =A25 -> 10 | B50: =J25 -> 19 | C50: =145+(B50-1)*15+(A50-1)*20 -> 595 | D50: =40+(B50-1)*10+(A50-1)*25 -> 445 | E50: =D50+(A50-1)*10 -> 535 | F50: =D50*1.5+(A50-1)*10 -> 757.5 | G50: =D50*2+(A50-1)*10 -> 980
...

Sheet Ennemis par acte
A1: Ennemis par acte
A2: combat_controller.dart initializeCombat : PV = round(maxHp × multPV), Puissance = round(baseDamage × multDégâts) ; note = tier × 15 + PV/4 + dégâts × 2 × (1 + crit/100)
A4: Type de nœud (1 normal, 2 élite, 3 boss) | B4: 1
A5: Le niveau du joueur par acte et les constantes viennent de l'onglet « Difficulté par acte ».
A6: Ennemi | B6: PV base | C6: Dégâts base | D6: Tier | E6: Crit | F6: XP base | G6: Or base
A7: Gobelin | B7: 28 | C7: 5 | D7: 1 | E7: 10 | F7: 35 | G7: 12
A8: Orc Furieux | B8: 50 | C8: 8 | D8: 3 | E8: 15 | F8: 100 | G8: 25
A9: Slime | B9: 18 | C9: 4 | D9: 1 | E9: 5 | F9: 25 | G9: 10
A10: Squelette | B10: 22 | C10: 8 | D10: 2 | E10: 10 | F10: 50 | G10: 15
A12: Acte | B12: Niv. ennemi | C12: × PV | D12: × dégâts | E12: Budget | F12: Gobelin PV | G12: dégâts | H12: note | I12: tient ? | J12: Orc Furieux PV | K12: dégâts | L12: note | M12: tient ? | N12: Slime PV | O12: dégâts | P12: note | Q12: tient ? | R12: Squelette PV | S12: dégâts | T12: note | U12: tient ?
A13: 1 | B13: =IF($B$4=3,'Difficulté par acte'!M16,IF($B$4=2,'Difficulté par acte'!L16,'Difficulté par acte'!K16)) -> 1 | C13: =IF($B$4=3,'Difficulté par acte'!R16,IF($B$4=2,'Difficulté par acte'!P16,'Difficulté par acte'!N16)) -> 1 | D13: =IF($B$4=3,'Difficulté par acte'!S16,IF($B$4=2,'Difficulté par acte'!Q16,'Difficulté par acte'!O16)) -> 1 | E13: =(40+('Difficulté par acte'!J16-1)*10+(A13-1)*25)*IF($B$4=3,2,IF($B$4=2,1.5,1))+(A13-1)*10 -> 40 | F13: =ROUND($B$7*C13,0) -> 28 | G13: =ROUND($C$7*D13,0) -> 5 | H13: =$D$7*15+F13/4+G13*2*(1+$E$7/100) -> 33 | I13: =IF(AND($D$7<=MIN(3,1+INT((A13-1)/5)),H13<=E13),"oui","non") -> oui | J13: =ROUND($B$8*C13,0) -> 50 | K13: =ROUND($C$8*D13,0) -> 8 | L13: =$D$8*15+J13/4+K13*2*(1+$E$8/100) -> 75.9 | M13: =IF(AND($D$8<=MIN(3,1+INT((A13-1)/5)),L13<=E13),"oui","non") -> non | N13: =ROUND($B$9*C13,0) -> 18 | O13: =ROUND($C$9*D13,0) -> 4 | P13: =$D$9*15+N13/4+O13*2*(1+$E$9/100) -> 27.9 | Q13: =IF(AND($D$9<=MIN(3,1+INT((A13-1)/5)),P13<=E13),"oui","non") -> oui | R13: =ROUND($B$10*C13,0) -> 22 | S13: =ROUND($C$10*D13,0) -> 8 | T13: =$D$10*15+R13/4+S13*2*(1+$E$10/100) -> 53.1 | U13: =IF(AND($D$10<=MIN(3,1+INT((A13-1)/5)),T13<=E13),"oui","non") -> non
A14: 2 | B14: =IF($B$4=3,'Difficulté par acte'!M17,IF($B$4=2,'Difficulté par acte'!L17,'Difficulté par acte'!K17)) -> 3 | C14: =IF($B$4=3,'Difficulté par acte'!R17,IF($B$4=2,'Difficulté par acte'!P17,'Difficulté par acte'!N17)) -> 1.176 | D14: =IF($B$4=3,'Difficulté par acte'!S17,IF($B$4=2,'Difficulté par acte'!Q17,'Difficulté par acte'!O17)) -> 1.1124 | E14: =(40+('Difficulté par acte'!J17-1)*10+(A14-1)*25)*IF($B$4=3,2,IF($B$4=2,1.5,1))+(A14-1)*10 -> 95 | F14: =ROUND($B$7*C14,0) -> 33 | G14: =ROUND($C$7*D14,0) -> 6 | H14: =$D$7*15+F14/4+G14*2*(1+$E$7/100) -> 36.45 | I14: =IF(AND($D$7<=MIN(3,1+INT((A14-1)/5)),H14<=E14),"oui","non") -> oui | J14: =ROUND($B$8*C14,0) -> 59 | K14: =ROUND($C$8*D14,0) -> 9 | L14: =$D$8*15+J14/4+K14*2*(1+$E$8/100) -> 80.45 | M14: =IF(AND($D$8<=MIN(3,1+INT((A14-1)/5)),L14<=E14),"oui","non") -> non | N14: =ROUND($B$9*C14,0) -> 21 | O14: =ROUND($C$9*D14,0) -> 4 | P14: =$D$9*15+N14/4+O14*2*(1+$E$9/100) -> 28.65 | Q14: =IF(AND($D$9<=MIN(3,1+INT((A14-1)/5)),P14<=E14),"oui","non") -> oui | R14: =ROUND($B$10*C14,0) -> 26 | S14: =ROUND($C$10*D14,0) -> 9 | T14: =$D$10*15+R14/4+S14*2*(1+$E$10/100) -> 56.3 | U14: =IF(AND($D$10<=MIN(3,1+INT((A14-1)/5)),T14<=E14),"oui","non") -> non
A15: 3 | B15: =IF($B$4=3,'Difficulté par acte'!M18,IF($B$4=2,'Difficulté par acte'!L18,'Difficulté par acte'!K18)) -> 5 | C15: =IF($B$4=3,'Difficulté par acte'!R18,IF($B$4=2,'Difficulté par acte'!P18,'Difficulté par acte'!N18)) -> 1.674 | D15: =IF($B$4=3,'Difficulté par acte'!S18,IF($B$4=2,'Difficulté par acte'!Q18,'Difficulté par acte'!O18)) -> 1.45 | E15: =(40+('Difficulté par acte'!J18-1)*10+(A15-1)*25)*IF($B$4=3,2,IF($B$4=2,1.5,1))+(A15-1)*10 -> 150 | F15: =ROUND($B$7*C15,0) -> 47 | G15: =ROUND($C$7*D15,0) -> 7 | H15: =$D$7*15+F15/4+G15*2*(1+$E$7/100) -> 42.15 | I15: =IF(AND($D$7<=MIN(3,1+INT((A15-1)/5)),H15<=E15),"oui","non") -> oui | J15: =ROUND($B$8*C15,0) -> 84 | K15: =ROUND($C$8*D15,0) -> 12 | L15: =$D$8*15+J15/4+K15*2*(1+$E$8/100) -> 93.6 | M15: =IF(AND($D$8<=MIN(3,1+INT((A15-1)/5)),L15<=E15),"oui","non") -> non | N15: =ROUND($B$9*C15,0) -> 30 | O15: =ROUND($C$9*D15,0) -> 6 | P15: =$D$9*15+N15/4+O15*2*(1+$E$9/100) -> 35.1 | Q15: =IF(AND($D$9<=MIN(3,1+INT((A15-1)/5)),P15<=E15),"oui","non") -> oui | R15: =ROUND($B$10*C15,0) -> 37 | S15: =ROUND($C$10*D15,0) -> 12 | T15: =$D$10*15+R15/4+S15*2*(1+$E$10/100) -> 65.65 | U15: =IF(AND($D$10<=MIN(3,1+INT((A15-1)/5)),T15<=E15),"oui","non") -> non
A16: 4 | B16: =IF($B$4=3,'Difficulté par acte'!M19,IF($B$4=2,'Difficulté par acte'!L19,'Difficulté par acte'!K19)) -> 7 | C16: =IF($B$4=3,'Difficulté par acte'!R19,IF($B$4=2,'Difficulté par acte'!P19,'Difficulté par acte'!N19)) -> 1.9278 | D16: =IF($B$4=3,'Difficulté par acte'!S19,IF($B$4=2,'Difficulté par acte'!Q19,'Difficulté par acte'!O19)) -> 1.5965 | E16: =(40+('Difficulté par acte'!J19-1)*10+(A16-1)*25)*IF($B$4=3,2,IF($B$4=2,1.5,1))+(A16-1)*10 -> 205 | F16: =ROUND($B$7*C16,0) -> 54 | G16: =ROUND($C$7*D16,0) -> 8 | H16: =$D$7*15+F16/4+G16*2*(1+$E$7/100) -> 46.1 | I16: =IF(AND($D$7<=MIN(3,1+INT((A16-1)/5)),H16<=E16),"oui","non") -> oui | J16: =ROUND($B$8*C16,0) -> 96 | K16: =ROUND($C$8*D16,0) -> 13 | L16: =$D$8*15+J16/4+K16*2*(1+$E$8/100) -> 98.9 | M16: =IF(AND($D$8<=MIN(3,1+INT((A16-1)/5)),L16<=E16),"oui","non") -> non | N16: =ROUND($B$9*C16,0) -> 35 | O16: =ROUND($C$9*D16,0) -> 6 | P16: =$D$9*15+N16/4+O16*2*(1+$E$9/100) -> 36.35 | Q16: =IF(AND($D$9<=MIN(3,1+INT((A16-1)/5)),P16<=E16),"oui","non") -> oui | R16: =ROUND($B$10*C16,0) -> 42 | S16: =ROUND($C$10*D16,0) -> 13 | T16: =$D$10*15+R16/4+S16*2*(1+$E$10/100) -> 69.1 | U16: =IF(AND($D$10<=MIN(3,1+INT((A16-1)/5)),T16<=E16),"oui","non") -> non
A17: 5 | B17: =IF($B$4=3,'Difficulté par acte'!M20,IF($B$4=2,'Difficulté par acte'!L20,'Difficulté par acte'!K20)) -> 9 | C17: =IF($B$4=3,'Difficulté par acte'!R20,IF($B$4=2,'Difficulté par acte'!P20,'Difficulté par acte'!N20)) -> 2.6973 | D17: =IF($B$4=3,'Difficulté par acte'!S20,IF($B$4=2,'Difficulté par acte'!Q20,'Difficulté par acte'!O20)) -> 2.0625 | E17: =(40+('Difficulté par acte'!J20-1)*10+(A17-1)*25)*IF($B$4=3,2,IF($B$4=2,1.5,1))+(A17-1)*10 -> 260 | F17: =ROUND($B$7*C17,0) -> 76 | G17: =ROUND($C$7*D17,0) -> 10 | H17: =$D$7*15+F17/4+G17*2*(1+$E$7/100) -> 56 | I17: =IF(AND($D$7<=MIN(3,1+INT((A17-1)/5)),H17<=E17),"oui","non") -> oui | J17: =ROUND($B$8*C17,0) -> 135 | K17: =ROUND($C$8*D17,0) -> 17 | L17: =$D$8*15+J17/4+K17*2*(1+$E$8/100) -> 117.85 | M17: =IF(AND($D$8<=MIN(3,1+INT((A17-1)/5)),L17<=E17),"oui","non") -> non | N17: =ROUND($B$9*C17,0) -> 49 | O17: =ROUND($C$9*D17,0) -> 8 | P17: =$D$9*15+N17/4+O17*2*(1+$E$9/100) -> 44.05 | Q17: =IF(AND($D$9<=MIN(3,1+INT((A17-1)/5)),P17<=E17),"oui","non") -> oui | R17: =ROUND($B$10*C17,0) -> 59 | S17: =ROUND($C$10*D17,0) -> 17 | T17: =$D$10*15+R17/4+S17*2*(1+$E$10/100) -> 82.15 | U17: =IF(AND($D$10<=MIN(3,1+INT((A17-1)/5)),T17<=E17),"oui","non") -> non
A18: 6 | B18: =IF($B$4=3,'Difficulté par acte'!M21,IF($B$4=2,'Difficulté par acte'!L21,'Difficulté par acte'!K21)) -> 11 | C18: =IF($B$4=3,'Difficulté par acte'!R21,IF($B$4=2,'Difficulté par acte'!P21,'Difficulté par acte'!N21)) -> 3.0618 | D18: =IF($B$4=3,'Difficulté par acte'!S21,IF($B$4=2,'Difficulté par acte'!Q21,'Difficulté par acte'!O21)) -> 2.253125 | E18: =(40+('Difficulté par acte'!J21-1)*10+(A18-1)*25)*IF($B$4=3,2,IF($B$4=2,1.5,1))+(A18-1)*10 -> 315 | F18: =ROUND($B$7*C18,0) -> 86 | G18: =ROUND($C$7*D18,0) -> 11 | H18: =$D$7*15+F18/4+G18*2*(1+$E$7/100) -> 60.7 | I18: =IF(AND($D$7<=MIN(3,1+INT((A18-1)/5)),H18<=E18),"oui","non") -> oui | J18: =ROUND($B$8*C18,0) -> 153 | K18: =ROUND($C$8*D18,0) -> 18 | L18: =$D$8*15+J18/4+K18*2*(1+$E$8/100) -> 124.65 | M18: =IF(AND($D$8<=MIN(3,1+INT((A18-1)/5)),L18<=E18),"oui","non") -> non | N18: =ROUND($B$9*C18,0) -> 55 | O18: =ROUND($C$9*D18,0) -> 9 | P18: =$D$9*15+N18/4+O18*2*(1+$E$9/100) -> 47.65 | Q18: =IF(AND($D$9<=MIN(3,1+INT((A18-1)/5)),P18<=E18),"oui","non") -> oui | R18: =ROUND($B$10*C18,0) -> 67 | S18: =ROUND($C$10*D18,0) -> 18 | T18: =$D$10*15+R18/4+S18*2*(1+$E$10/100) -> 86.35 | U18: =IF(AND($D$10<=MIN(3,1+INT((A18-1)/5)),T18<=E18),"oui","non") -> oui
A19: 7 | B19: =IF($B$4=3,'Difficulté par acte'!M22,IF($B$4=2,'Difficulté par acte'!L22,'Difficulté par acte'!K22)) -> 13 | C19: =IF($B$4=3,'Difficulté par acte'!R22,IF($B$4=2,'Difficulté par acte'!P22,'Difficulté par acte'!N22)) -> 4.231845 | D19: =IF($B$4=3,'Difficulté par acte'!S22,IF($B$4=2,'Difficulté par acte'!Q22,'Difficulté par acte'!O22)) -> 2.890625 | E19: =(40+('Difficulté par acte'!J22-1)*10+(A19-1)*25)*IF($B$4=3,2,IF($B$4=2,1.5,1))+(A19-1)*10 -> 370 | F19: =ROUND($B$7*C19,0) -> 118 | G19: =ROUND($C$7*D19,0) -> 14 | H19: =$D$7*15+F19/4+G19*2*(1+$E$7/100) -> 75.3 | I19: =IF(AND($D$7<=MIN(3,1+INT((A19-1)/5)),H19<=E19),"oui","non") -> oui | J19: =ROUND($B$8*C19,0) -> 212 | K19: =ROUND($C$8*D19,0) -> 23 | L19: =$D$8*15+J19/4+K19*2*(1+$E$8/100) -> 150.9 | M19: =IF(AND($D$8<=MIN(3,1+INT((A19-1)/5)),L19<=E19),"oui","non") -> non | N19: =ROUND($B$9*C19,0) -> 76 | O19: =ROUND($C$9*D19,0) -> 12 | P19: =$D$9*15+N19/4+O19*2*(1+$E$9/100) -> 59.2 | Q19: =IF(AND($D$9<=MIN(3,1+INT((A19-1)/5)),P19<=E19),"oui","non") -> oui | R19: =ROUND($B$10*C19,0) -> 93 | S19: =ROUND($C$10*D19,0) -> 23 | T19: =$D$10*15+R19/4+S19*2*(1+$E$10/100) -> 103.85 | U19: =IF(AND($D$10<=MIN(3,1+INT((A19-1)/5)),T19<=E19),"oui","non") -> oui
A20: 8 | B20: =IF($B$4=3,'Difficulté par acte'!M23,IF($B$4=2,'Difficulté par acte'!L23,'Difficulté par acte'!K23)) -> 15 | C20: =IF($B$4=3,'Difficulté par acte'!R23,IF($B$4=2,'Difficulté par acte'!P23,'Difficulté par acte'!N23)) -> 4.7534445 | D20: =IF($B$4=3,'Difficulté par acte'!S23,IF($B$4=2,'Difficulté par acte'!Q23,'Difficulté par acte'!O23)) -> 3.1382812 | E20: =(40+('Difficulté par acte'!J23-1)*10+(A20-1)*25)*IF($B$4=3,2,IF($B$4=2,1.5,1))+(A20-1)*10 -> 425 | F20: =ROUND($B$7*C20,0) -> 133 | G20: =ROUND($C$7*D20,0) -> 16 | H20: =$D$7*15+F20/4+G20*2*(1+$E$7/100) -> 83.45 | I20: =IF(AND($D$7<=MIN(3,1+INT((A20-1)/5)),H20<=E20),"oui","non") -> oui | J20: =ROUND($B$8*C20,0) -> 238 | K20: =ROUND($C$8*D20,0) -> 25 | L20: =$D$8*15+J20/4+K20*2*(1+$E$8/100) -> 162 | M20: =IF(AND($D$8<=MIN(3,1+INT((A20-1)/5)),L20<=E20),"oui","non") -> non | N20: =ROUND($B$9*C20,0) -> 86 | O20: =ROUND($C$9*D20,0) -> 13 | P20: =$D$9*15+N20/4+O20*2*(1+$E$9/100) -> 63.8 | Q20: =IF(AND($D$9<=MIN(3,1+INT((A20-1)/5)),P20<=E20),"oui","non") -> oui | R20: =ROUND($B$10*C20,0) -> 105 | S20: =ROUND($C$10*D20,0) -> 25 | T20: =$D$10*15+R20/4+S20*2*(1+$E$10/100) -> 111.25 | U20: =IF(AND($D$10<=MIN(3,1+INT((A20-1)/5)),T20<=E20),"oui","non") -> oui
A21: 9 | B21: =IF($B$4=3,'Difficulté par acte'!M24,IF($B$4=2,'Difficulté par acte'!L24,'Difficulté par acte'!K24)) -> 17 | C21: =IF($B$4=3,'Difficulté par acte'!R24,IF($B$4=2,'Difficulté par acte'!P24,'Difficulté par acte'!N24)) -> 6.5101523 | D21: =IF($B$4=3,'Difficulté par acte'!S24,IF($B$4=2,'Difficulté par acte'!Q24,'Difficulté par acte'!O24)) -> 4.0039062 | E21: =(40+('Difficulté par acte'!J24-1)*10+(A21-1)*25)*IF($B$4=3,2,IF($B$4=2,1.5,1))+(A21-1)*10 -> 480 | F21: =ROUND($B$7*C21,0) -> 182 | G21: =ROUND($C$7*D21,0) -> 20 | H21: =$D$7*15+F21/4+G21*2*(1+$E$7/100) -> 104.5 | I21: =IF(AND($D$7<=MIN(3,1+INT((A21-1)/5)),H21<=E21),"oui","non") -> oui | J21: =ROUND($B$8*C21,0) -> 326 | K21: =ROUND($C$8*D21,0) -> 32 | L21: =$D$8*15+J21/4+K21*2*(1+$E$8/100) -> 200.1 | M21: =IF(AND($D$8<=MIN(3,1+INT((A21-1)/5)),L21<=E21),"oui","non") -> non | N21: =ROUND($B$9*C21,0) -> 117 | O21: =ROUND($C$9*D21,0) -> 16 | P21: =$D$9*15+N21/4+O21*2*(1+$E$9/100) -> 77.85 | Q21: =IF(AND($D$9<=MIN(3,1+INT((A21-1)/5)),P21<=E21),"oui","non") -> oui | R21: =ROUND($B$10*C21,0) -> 143 | S21: =ROUND($C$10*D21,0) -> 32 | T21: =$D$10*15+R21/4+S21*2*(1+$E$10/100) -> 136.15 | U21: =IF(AND($D$10<=MIN(3,1+INT((A21-1)/5)),T21<=E21),"oui","non") -> oui
A22: 10 | B22: =IF($B$4=3,'Difficulté par acte'!M25,IF($B$4=2,'Difficulté par acte'!L25,'Difficulté par acte'!K25)) -> 19 | C22: =IF($B$4=3,'Difficulté par acte'!R25,IF($B$4=2,'Difficulté par acte'!P25,'Difficulté par acte'!N25)) -> 7.2541697 | D22: =IF($B$4=3,'Difficulté par acte'!S25,IF($B$4=2,'Difficulté par acte'!Q25,'Difficulté par acte'!O25)) -> 4.3251953 | E22: =(40+('Difficulté par acte'!J25-1)*10+(A22-1)*25)*IF($B$4=3,2,IF($B$4=2,1.5,1))+(A22-1)*10 -> 535 | F22: =ROUND($B$7*C22,0) -> 203 | G22: =ROUND($C$7*D22,0) -> 22 | H22: =$D$7*15+F22/4+G22*2*(1+$E$7/100) -> 114.15 | I22: =IF(AND($D$7<=MIN(3,1+INT((A22-1)/5)),H22<=E22),"oui","non") -> oui | J22: =ROUND($B$8*C22,0) -> 363 | K22: =ROUND($C$8*D22,0) -> 35 | L22: =$D$8*15+J22/4+K22*2*(1+$E$8/100) -> 216.25 | M22: =IF(AND($D$8<=MIN(3,1+INT((A22-1)/5)),L22<=E22),"oui","non") -> non | N22: =ROUND($B$9*C22,0) -> 131 | O22: =ROUND($C$9*D22,0) -> 17 | P22: =$D$9*15+N22/4+O22*2*(1+$E$9/100) -> 83.45 | Q22: =IF(AND($D$9<=MIN(3,1+INT((A22-1)/5)),P22<=E22),"oui","non") -> oui | R22: =ROUND($B$10*C22,0) -> 160 | S22: =ROUND($C$10*D22,0) -> 35 | T22: =$D$10*15+R22/4+S22*2*(1+$E$10/100) -> 147 | U22: =IF(AND($D$10<=MIN(3,1+INT((A22-1)/5)),T22<=E22),"oui","non") -> oui
A23: 11 | B23: =IF($B$4=3,'Difficulté par acte'!M26,IF($B$4=2,'Difficulté par acte'!L26,'Difficulté par acte'!K26)) -> 21 | C23: =IF($B$4=3,'Difficulté par acte'!R26,IF($B$4=2,'Difficulté par acte'!P26,'Difficulté par acte'!N26)) -> 9.8648736 | D23: =IF($B$4=3,'Difficulté par acte'!S26,IF($B$4=2,'Difficulté par acte'!Q26,'Difficulté par acte'!O26)) -> 5.4931641 | E23: =(40+('Difficulté par acte'!J26-1)*10+(A23-1)*25)*IF($B$4=3,2,IF($B$4=2,1.5,1))+(A23-1)*10 -> 590 | F23: =ROUND($B$7*C23,0) -> 276 | G23: =ROUND($C$7*D23,0) -> 27 | H23: =$D$7*15+F23/4+G23*2*(1+$E$7/100) -> 143.4 | I23: =IF(AND($D$7<=MIN(3,1+INT((A23-1)/5)),H23<=E23),"oui","non") -> oui | J23: =ROUND($B$8*C23,0) -> 493 | K23: =ROUND($C$8*D23,0) -> 44 | L23: =$D$8*15+J23/4+K23*2*(1+$E$8/100) -> 269.45 | M23: =IF(AND($D$8<=MIN(3,1+INT((A23-1)/5)),L23<=E23),"oui","non") -> oui | N23: =ROUND($B$9*C23,0) -> 178 | O23: =ROUND($C$9*D23,0) -> 22 | P23: =$D$9*15+N23/4+O23*2*(1+$E$9/100) -> 105.7 | Q23: =IF(AND($D$9<=MIN(3,1+INT((A23-1)/5)),P23<=E23),"oui","non") -> oui | R23: =ROUND($B$10*C23,0) -> 217 | S23: =ROUND($C$10*D23,0) -> 44 | T23: =$D$10*15+R23/4+S23*2*(1+$E$10/100) -> 181.05 | U23: =IF(AND($D$10<=MIN(3,1+INT((A23-1)/5)),T23<=E23),"oui","non") -> oui
A24: 12 | B24: =IF($B$4=3,'Difficulté par acte'!M27,IF($B$4=2,'Difficulté par acte'!L27,'Difficulté par acte'!K27)) -> 23 | C24: =IF($B$4=3,'Difficulté par acte'!R27,IF($B$4=2,'Difficulté par acte'!P27,'Difficulté par acte'!N27)) -> 10.923105 | D24: =IF($B$4=3,'Difficulté par acte'!S27,IF($B$4=2,'Difficulté par acte'!Q27,'Difficulté par acte'!O27)) -> 5.9094238 | E24: =(40+('Difficulté par acte'!J27-1)*10+(A24-1)*25)*IF($B$4=3,2,IF($B$4=2,1.5,1))+(A24-1)*10 -> 645 | F24: =ROUND($B$7*C24,0) -> 306 | G24: =ROUND($C$7*D24,0) -> 30 | H24: =$D$7*15+F24/4+G24*2*(1+$E$7/100) -> 157.5 | I24: =IF(AND($D$7<=MIN(3,1+INT((A24-1)/5)),H24<=E24),"oui","non") -> oui | J24: =ROUND($B$8*C24,0) -> 546 | K24: =ROUND($C$8*D24,0) -> 47 | L24: =$D$8*15+J24/4+K24*2*(1+$E$8/100) -> 289.6 | M24: =IF(AND($D$8<=MIN(3,1+INT((A24-1)/5)),L24<=E24),"oui","non") -> oui | N24: =ROUND($B$9*C24,0) -> 197 | O24: =ROUND($C$9*D24,0) -> 24 | P24: =$D$9*15+N24/4+O24*2*(1+$E$9/100) -> 114.65 | Q24: =IF(AND($D$9<=MIN(3,1+INT((A24-1)/5)),P24<=E24),"oui","non") -> oui | R24: =ROUND($B$10*C24,0) -> 240 | S24: =ROUND($C$10*D24,0) -> 47 | T24: =$D$10*15+R24/4+S24*2*(1+$E$10/100) -> 193.4 | U24: =IF(AND($D$10<=MIN(3,1+INT((A24-1)/5)),T24<=E24),"oui","non") -> oui
... A32: 20 | B32: =IF($B$4=3,'Difficulté par acte'!M35,IF($B$4=2,'Difficulté par acte'!L35,'Difficulté par acte'!K35)) -> 39 | C32: =IF($B$4=3,'Difficulté par acte'!R35,IF($B$4=2,'Difficulté par acte'!P35,'Difficulté par acte'!N35)) -> 51.294058 | D32: =IF($B$4=3,'Difficulté par acte'!S35,IF($B$4=2,'Difficulté par acte'!Q35,'Difficulté par acte'!O35)) -> 19.338727 | E32: =(40+('Difficulté par acte'!J35-1)*10+(A32-1)*25)*IF($B$4=3,2,IF($B$4=2,1.5,1))+(A32-1)*10 -> 1085 | F32: =ROUND($B$7*C32,0) -> 1436 | G32: =ROUND($C$7*D32,0) -> 97 | H32: =$D$7*15+F32/4+G32*2*(1+$E$7/100) -> 587.4 | I32: =IF(AND($D$7<=MIN(3,1+INT((A32-1)/5)),H32<=E32),"oui","non") -> oui | J32: =ROUND($B$8*C32,0) -> 2565 | K32: =ROUND($C$8*D32,0) -> 155 | L32: =$D$8*15+J32/4+K32*2*(1+$E$8/100) -> 1042.75 | M32: =IF(AND($D$8<=MIN(3,1+INT((A32-1)/5)),L32<=E32),"oui","non") -> oui | N32: =ROUND($B$9*C32,0) -> 923 | O32: =ROUND($C$9*D32,0) -> 77 | P32: =$D$9*15+N32/4+O32*2*(1+$E$9/100) -> 407.45 | Q32: =IF(AND($D$9<=MIN(3,1+INT((A32-1)/5)),P32<=E32),"oui","non") -> oui | R32: =ROUND($B$10*C32,0) -> 1128 | S32: =ROUND($C$10*D32,0) -> 155 | T32: =$D$10*15+R32/4+S32*2*(1+$E$10/100) -> 653 | U32: =IF(AND($D$10<=MIN(3,1+INT((A32-1)/5)),T32<=E32),"oui","non") -> oui
A33: « tient ? » : le tier est débloqué ET la note ≤ budget à ratio de puissance 1. Les tiers 2 et 3 (Squelette, Orc) n'apparaissent qu'aux actes 6 et 11.

Sheet Calculateur de combat
A1: Calculateur d'un combat
A2: EncounterSystem.calculateBudget / getEnemyLevel / getHpMultiplier / getDamageMultiplier / calculateCombatRating ; RewardController.handleVictory pour l'XP et l'or
A4: Entrées
A5: Acte | B5: 1
A6: Niveau du joueur | B6: 1
A7: PV max | B7: 100 | C7: Paladin 100, Berserker 80, Mage 60
A8: Puissance permanente | B8: 0
A9: Mana max | B9: 3
A10: Reliques portées | B10: 0
A11: Somme des rangs de fusion du deck | B11: 0 | C11: DeckState.fusionRankSum : 1 par peu commune, 2 par rare, 3, 4
A12: Type de nœud (1 normal, 2 élite, 3 boss) | B12: 1
A13: Boss « XP » (1 = oui) | B13: 0 | C13: or et XP × 3
A15: Budget
A16: Puissance du joueur | B16: =$B$7+$B$8*10+$B$9*15+$B$10*5+$B$11*2 -> 145 | C16: PV max + 10 × Puissance + 15 × Mana max + 5 × reliques + 2 × Σ rangs
A17: Puissance attendue | B17: =145+($B$6-1)*15+($B$5-1)*20 -> 145
A18: Ratio | B18: =$B$16/$B$17 -> 1
A19: Modificateur (amorti ×0,5) | B19: =1+($B$18-1)*0.5 -> 1
A20: Budget de base | B20: =40+($B$6-1)*10+($B$5-1)*25 -> 40
A21: Multiplicateur de nœud (budget) | B21: =IF($B$12=3,2,IF($B$12=2,1.5,1)) -> 1
A22: Budget final | B22: =$B$20*$B$19*$B$21+($B$5-1)*10 -> 40
A23: Ennemis max | B23: =IF($B$12=3,1+INT(($B$5-1)/5),IF($B$12=2,1+INT(($B$5-1)/2),$B$5)) -> 1 | C23: 5 actifs à la fois, le reste en réserve
A25: Multiplicateurs
A26: Niveau des ennemis | B26: =MAX(1,$B$6+IF($B$12=3,2,IF($B$12=2,1,0))) -> 1
A27: Facteur d'acte PV | B27: =1.35^INT(($B$5-1)/2)*(1+0.05*MOD($B$5-1,2)) -> 1
A28: Facteur d'acte dégâts | B28: =1.25^INT(($B$5-1)/2)*(1+0.03*MOD($B$5-1,2)) -> 1
A29: Multiplicateur de nœud (stats) | B29: =IF($B$12=3,3,IF($B$12=2,1.5,1)) -> 1
A30: Multiplicateur PV | B30: =(1+0.06*($B$26-1))*$B$27*$B$29 -> 1
A31: Multiplicateur dégâts | B31: =(1+0.04*($B$26-1))*$B$28*$B$29 -> 1
A32: Tier débloqué | B32: =MIN(3,1+INT(($B$5-1)/5)) -> 1
A33: Multiplicateur de récompense (niveau) | B33: =1+0.1*($B$26-1) -> 1 | C33: XP et or × (1 + 0,10 × (niveau − 1)), arrondi
A35: Ennemi | B35: Tier | C35: PV | D35: Puissance (dégâts) | E35: Note de menace | F35: Éligible ? | G35: Tient dans le budget ? | H35: XP rapportée | I35: Or rapporté | J35: Intentions effectives (cycle)
A36: Gobelin | B36: 1 | C36: =ROUND(28*$B$30,0) -> 28 | D36: =ROUND(5*$B$31,0) -> 5 | E36: =B36*15+C36/4+D36*2*(1+10/100) -> 33 | F36: =IF(B36<=$B$32,"oui","non") -> oui | G36: =IF(AND(F36="oui",E36<=$B$22),"oui","non") -> oui | H36: =ROUND(35*$B$33,0)*IF($B$13=1,3,1) -> 35 | I36: =ROUND(12*$B$33,0)*IF($B$13=1,3,1) -> 12 | J36: ="attack "&ROUND(5*D36/5,0) -> attack 5
A37: Orc Furieux | B37: 3 | C37: =ROUND(50*$B$30,0) -> 50 | D37: =ROUND(8*$B$31,0) -> 8 | E37: =B37*15+C37/4+D37*2*(1+15/100) -> 75.9 | F37: =IF(B37<=$B$32,"oui","non") -> non | G37: =IF(AND(F37="oui",E37<=$B$22),"oui","non") -> non | H37: =ROUND(100*$B$33,0)*IF($B$13=1,3,1) -> 100 | I37: =ROUND(25*$B$33,0)*IF($B$13=1,3,1) -> 25 | J37: ="attack "&ROUND(8*D37/8,0)&" → "&"buff 2"&" → "&"attack "&ROUND(12*D37/8,0) -> attack 8 → buff 2 → attack 12
A38: Slime | B38: 1 | C38: =ROUND(18*$B$30,0) -> 18 | D38: =ROUND(4*$B$31,0) -> 4 | E38: =B38*15+C38/4+D38*2*(1+5/100) -> 27.9 | F38: =IF(B38<=$B$32,"oui","non") -> oui | G38: =IF(AND(F38="oui",E38<=$B$22),"oui","non") -> oui | H38: =ROUND(25*$B$33,0)*IF($B$13=1,3,1) -> 25 | I38: =ROUND(10*$B$33,0)*IF($B$13=1,3,1) -> 10 | J38: ="attack "&ROUND(4*D38/4,0) -> attack 4
A39: Squelette | B39: 2 | C39: =ROUND(22*$B$30,0) -> 22 | D39: =ROUND(8*$B$31,0) -> 8 | E39: =B39*15+C39/4+D39*2*(1+10/100) -> 53.1 | F39: =IF(B39<=$B$32,"oui","non") -> non | G39: =IF(AND(F39="oui",E39<=$B$22),"oui","non") -> non | H39: =ROUND(50*$B$33,0)*IF($B$13=1,3,1) -> 50 | I39: =ROUND(15*$B$33,0)*IF($B$13=1,3,1) -> 15 | J39: ="attack "&ROUND(8*D39/8,0)&" → "&"attack "&ROUND(10*D39/8,0) -> attack 8 → attack 10
A40: Attaque effective d'une intention = round(valeur × Puissance de spawn ÷ dégâts de base), + la Puissance gagnée en combat (buff), ÷ 2 arrondi si Gelé (EnemyInstance.effectiveIntent).
A41: Le générateur tire un candidat qui tient, retire sa note du budget, et recommence jusqu'au max d'ennemis ou jusqu'à ce que plus rien ne tienne ; sans aucun candidat, l'ennemi de plus petite note sort seul.

Sheet Courbe d'XP
A1: Courbe d'XP
A2: assets/data/xp_curve.json + PlayerStatsManager.gainXp : le prix d'un niveau est celui de l'acte courant, relu à chaque niveau ; surplus conservé
A4: A. Prix d'un niveau, par acte (xpPerLevelByAct)
A5: Acte | B5: XP par niveau | C5: Niveaux par acte (cible D24) | D5: XP à gagner dans l'acte | E5: XP cumulée (fin d'acte) | F5: Variation vs acte précédent
A6: 1 | B6: 115 | C6: 2 | D6: =B6*C6 -> 230 | E6: =D6 -> 230
A7: 2 | B7: 200 | C7: 2 | D7: =B7*C7 -> 400 | E7: =E6+D7 -> 630 | F7: =B7/B6-1 -> 0.73913043
A8: 3 | B8: 310 | C8: 2 | D8: =B8*C8 -> 620 | E8: =E7+D8 -> 1250 | F8: =B8/B7-1 -> 0.55
A9: 4 | B9: 480 | C9: 2 | D9: =B9*C9 -> 960 | E9: =E8+D9 -> 2210 | F9: =B9/B8-1 -> 0.5483871
A10: 5 | B10: 590 | C10: 2 | D10: =B10*C10 -> 1180 | E10: =E9+D10 -> 3390 | F10: =B10/B9-1 -> 0.22916667
A11: 6 | B11: 775 | C11: 2 | D11: =B11*C11 -> 1550 | E11: =E10+D11 -> 4940 | F11: =B11/B10-1 -> 0.31355932
A12: 7 | B12: 955 | C12: 2 | D12: =B12*C12 -> 1910 | E12: =E11+D12 -> 6850 | F12: =B12/B11-1 -> 0.23225806
A13: 8 | B13: 1100 | C13: 2 | D13: =B13*C13 -> 2200 | E13: =E12+D13 -> 9050 | F13: =B13/B12-1 -> 0.15183246
A14: 9 | B14: 1040 | C14: 2 | D14: =B14*C14 -> 2080 | E14: =E13+D14 -> 11130 | F14: =B14/B13-1 -> -0.054545455
A15: 10 | B15: 1185 | C15: 2 | D15: =B15*C15 -> 2370 | E15: =E14+D15 -> 13500 | F15: =B15/B14-1 -> 0.13942308
A16: 11 | B16: 1370 | C16: 2 | D16: =B16*C16 -> 2740 | E16: =E15+D16 -> 16240 | F16: =B16/B15-1 -> 0.15611814
A17: 12 | B17: 1370 | C17: 2 | D17: =B17*C17 -> 2740 | E17: =E16+D17 -> 18980 | F17: =B17/B16-1 -> 0
A18: 13 | B18: 1300 | C18: 2 | D18: =B18*C18 -> 2600 | E18: =E17+D18 -> 21580 | F18: =B18/B17-1 -> -0.051094891
... A20: 15 | B20: 1015 | C20: 2 | D20: =B20*C20 -> 2030 | E20: =E19+D20 -> 26360 | F20: =B20/B19-1 -> -0.26181818
A21: 16+ | B21: =B20 -> 1015 | C21: 2 | F21: la dernière valeur vaut au-delà de la table
A22: Le palier baisse de l'acte 8 (1100) à l'acte 9 (1040) et de 11-12 (1370) à 13 (1300) : une XP accumulée sous l'ancien palier mais au-dessus du nouveau donne le niveau au gain suivant.
A24: B. XP et or d'un ennemi selon son niveau (multiplicateur 1 + 0,10 × (niveau − 1), arrondi)
A25: Niveau d'ennemi | B25: Multiplicateur | C25: XP Gobelin | D25: XP Orc Furieux | E25: XP Slime | F25: XP Squelette | G25: Or Gobelin | H25: Or Orc Furieux | I25: Or Slime | J25: Or Squelette
A26: 1 | B26: =1+0.1*(A26-1) -> 1 | C26: =ROUND(35*B26,0) -> 35 | D26: =ROUND(100*B26,0) -> 100 | E26: =ROUND(25*B26,0) -> 25 | F26: =ROUND(50*B26,0) -> 50 | G26: =ROUND(12*B26,0) -> 12 | H26: =ROUND(25*B26,0) -> 25 | I26: =ROUND(10*B26,0) -> 10 | J26: =ROUND(15*B26,0) -> 15
A27: 2 | B27: =1+0.1*(A27-1) -> 1.1 | C27: =ROUND(35*B27,0) -> 39 | D27: =ROUND(100*B27,0) -> 110 | E27: =ROUND(25*B27,0) -> 28 | F27: =ROUND(50*B27,0) -> 55 | G27: =ROUND(12*B27,0) -> 13 | H27: =ROUND(25*B27,0) -> 28 | I27: =ROUND(10*B27,0) -> 11 | J27: =ROUND(15*B27,0) -> 17
A28: 3 | B28: =1+0.1*(A28-1) -> 1.2 | C28: =ROUND(35*B28,0) -> 42 | D28: =ROUND(100*B28,0) -> 120 | E28: =ROUND(25*B28,0) -> 30 | F28: =ROUND(50*B28,0) -> 60 | G28: =ROUND(12*B28,0) -> 14 | H28: =ROUND(25*B28,0) -> 30 | I28: =ROUND(10*B28,0) -> 12 | J28: =ROUND(15*B28,0) -> 18
A29: 4 | B29: =1+0.1*(A29-1) -> 1.3 | C29: =ROUND(35*B29,0) -> 46 | D29: =ROUND(100*B29,0) -> 130 | E29: =ROUND(25*B29,0) -> 33 | F29: =ROUND(50*B29,0) -> 65 | G29: =ROUND(12*B29,0) -> 16 | H29: =ROUND(25*B29,0) -> 33 | I29: =ROUND(10*B29,0) -> 13 | J29: =ROUND(15*B29,0) -> 20
A30: 5 | B30: =1+0.1*(A30-1) -> 1.4 | C30: =ROUND(35*B30,0) -> 49 | D30: =ROUND(100*B30,0) -> 140 | E30: =ROUND(25*B30,0) -> 35 | F30: =ROUND(50*B30,0) -> 70 | G30: =ROUND(12*B30,0) -> 17 | H30: =ROUND(25*B30,0) -> 35 | I30: =ROUND(10*B30,0) -> 14 | J30: =ROUND(15*B30,0) -> 21
A31: 6 | B31: =1+0.1*(A31-1) -> 1.5 | C31: =ROUND(35*B31,0) -> 53 | D31: =ROUND(100*B31,0) -> 150 | E31: =ROUND(25*B31,0) -> 38 | F31: =ROUND(50*B31,0) -> 75 | G31: =ROUND(12*B31,0) -> 18 | H31: =ROUND(25*B31,0) -> 38 | I31: =ROUND(10*B31,0) -> 15 | J31: =ROUND(15*B31,0) -> 23
A32: 7 | B32: =1+0.1*(A32-1) -> 1.6 | C32: =ROUND(35*B32,0) -> 56 | D32: =ROUND(100*B32,0) -> 160 | E32: =ROUND(25*B32,0) -> 40 | F32: =ROUND(50*B32,0) -> 80 | G32: =ROUND(12*B32,0) -> 19 | H32: =ROUND(25*B32,0) -> 40 | I32: =ROUND(10*B32,0) -> 16 | J32: =ROUND(15*B32,0) -> 24
A33: 8 | B33: =1+0.1*(A33-1) -> 1.7 | C33: =ROUND(35*B33,0) -> 60 | D33: =ROUND(100*B33,0) -> 170 | E33: =ROUND(25*B33,0) -> 43 | F33: =ROUND(50*B33,0) -> 85 | G33: =ROUND(12*B33,0) -> 20 | H33: =ROUND(25*B33,0) -> 43 | I33: =ROUND(10*B33,0) -> 17 | J33: =ROUND(15*B33,0) -> 26
A34: 9 | B34: =1+0.1*(A34-1) -> 1.8 | C34: =ROUND(35*B34,0) -> 63 | D34: =ROUND(100*B34,0) -> 180 | E34: =ROUND(25*B34,0) -> 45 | F34: =ROUND(50*B34,0) -> 90 | G34: =ROUND(12*B34,0) -> 22 | H34: =ROUND(25*B34,0) -> 45 | I34: =ROUND(10*B34,0) -> 18 | J34: =ROUND(15*B34,0) -> 27
A35: 10 | B35: =1+0.1*(A35-1) -> 1.9 | C35: =ROUND(35*B35,0) -> 67 | D35: =ROUND(100*B35,0) -> 190 | E35: =ROUND(25*B35,0) -> 48 | F35: =ROUND(50*B35,0) -> 95 | G35: =ROUND(12*B35,0) -> 23 | H35: =ROUND(25*B35,0) -> 48 | I35: =ROUND(10*B35,0) -> 19 | J35: =ROUND(15*B35,0) -> 29
A36: 11 | B36: =1+0.1*(A36-1) -> 2 | C36: =ROUND(35*B36,0) -> 70 | D36: =ROUND(100*B36,0) -> 200 | E36: =ROUND(25*B36,0) -> 50 | F36: =ROUND(50*B36,0) -> 100 | G36: =ROUND(12*B36,0) -> 24 | H36: =ROUND(25*B36,0) -> 50 | I36: =ROUND(10*B36,0) -> 20 | J36: =ROUND(15*B36,0) -> 30
A37: 12 | B37: =1+0.1*(A37-1) -> 2.1 | C37: =ROUND(35*B37,0) -> 74 | D37: =ROUND(100*B37,0) -> 210 | E37: =ROUND(25*B37,0) -> 53 | F37: =ROUND(50*B37,0) -> 105 | G37: =ROUND(12*B37,0) -> 25 | H37: =ROUND(25*B37,0) -> 53 | I37: =ROUND(10*B37,0) -> 21 | J37: =ROUND(15*B37,0) -> 32
... A65: 40 | B65: =1+0.1*(A65-1) -> 4.9 | C65: =ROUND(35*B65,0) -> 172 | D65: =ROUND(100*B65,0) -> 490 | E65: =ROUND(25*B65,0) -> 123 | F65: =ROUND(50*B65,0) -> 245 | G65: =ROUND(12*B65,0) -> 59 | H65: =ROUND(25*B65,0) -> 123 | I65: =ROUND(10*B65,0) -> 49 | J65: =ROUND(15*B65,0) -> 74
A67: C. Combien d'ennemis pour un niveau ? (ennemis au niveau du joueur, combat normal)
A68: Niveau joueur en début d'acte = 1 + 2 × (acte − 1) (scénario de l'onglet Difficulté) ; les kills nécessaires = XP du palier ÷ XP d'un ennemi à ce niveau.
A69: Acte | B69: Niveau joueur | C69: XP du palier | D69: XP Slime | E69: Kills Slime | F69: XP Gobelin | G69: Kills Gobelin | H69: XP Squelette (acte ≥ 6) | I69: Kills Squelette | J69: XP Orc (acte ≥ 11)
A70: 1 | B70: =1+2*(A70-1) -> 1 | C70: =INDEX($B$6:$B$20,MIN(A70,15)) -> 115 | D70: =ROUND(25*(1+0.1*(B70-1)),0) -> 25 | E70: =C70/D70 -> 4.6 | F70: =ROUND(35*(1+0.1*(B70-1)),0) -> 35 | G70: =C70/F70 -> 3.2857143 | H70: =ROUND(50*(1+0.1*(B70-1)),0) -> 50 | I70: =C70/H70 -> 2.3 | J70: =ROUND(100*(1+0.1*(B70-1)),0) -> 100
A71: 2 | B71: =1+2*(A71-1) -> 3 | C71: =INDEX($B$6:$B$20,MIN(A71,15)) -> 200 | D71: =ROUND(25*(1+0.1*(B71-1)),0) -> 30 | E71: =C71/D71 -> 6.6666667 | F71: =ROUND(35*(1+0.1*(B71-1)),0) -> 42 | G71: =C71/F71 -> 4.7619048 | H71: =ROUND(50*(1+0.1*(B71-1)),0) -> 60 | I71: =C71/H71 -> 3.3333333 | J71: =ROUND(100*(1+0.1*(B71-1)),0) -> 120
...

Sheet Économie (or)
A1: Économie : l'or
A2: InventoryController (50 or de départ), RewardController (or des ennemis), ShopController/ShopScreen (prix), ForgeRuneRules (affûtage, Puits), événements
A4: A. Entrées d'or
A5: Or de départ | B5: 50 | C5: RunController.startNewRun → reset(initialGold: 50)
A6: Ennemi | B6: Or de base | C6: Niveau 1 | D6: Niveau 5 | E6: Niveau 10 | F6: Niveau 20 | G6: Niveau 30 | H6: Boss « XP » : × 3
A7: Gobelin | B7: 12 | C7: =ROUND(B7*(1+0.1*(1-1)),0) -> 12 | D7: =ROUND(B7*(1+0.1*(5-1)),0) -> 17 | E7: =ROUND(B7*(1+0.1*(10-1)),0) -> 23 | F7: =ROUND(B7*(1+0.1*(20-1)),0) -> 35 | G7: =ROUND(B7*(1+0.1*(30-1)),0) -> 47 | H7: oui
A8: Orc Furieux | B8: 25 | C8: =ROUND(B8*(1+0.1*(1-1)),0) -> 25 | D8: =ROUND(B8*(1+0.1*(5-1)),0) -> 35 | E8: =ROUND(B8*(1+0.1*(10-1)),0) -> 48 | F8: =ROUND(B8*(1+0.1*(20-1)),0) -> 73 | G8: =ROUND(B8*(1+0.1*(30-1)),0) -> 98 | H8: oui
A9: Slime | B9: 10 | C9: =ROUND(B9*(1+0.1*(1-1)),0) -> 10 | D9: =ROUND(B9*(1+0.1*(5-1)),0) -> 14 | E9: =ROUND(B9*(1+0.1*(10-1)),0) -> 19 | F9: =ROUND(B9*(1+0.1*(20-1)),0) -> 29 | G9: =ROUND(B9*(1+0.1*(30-1)),0) -> 39 | H9: oui
A10: Squelette | B10: 15 | C10: =ROUND(B10*(1+0.1*(1-1)),0) -> 15 | D10: =ROUND(B10*(1+0.1*(5-1)),0) -> 21 | E10: =ROUND(B10*(1+0.1*(10-1)),0) -> 29 | F10: =ROUND(B10*(1+0.1*(20-1)),0) -> 44 | G10: =ROUND(B10*(1+0.1*(30-1)),0) -> 59 | H10: oui
A12: Événement — choix | B12: Or
A13: Le Feu de Camp Abandonné — Consommer les provisions abandonnées (-25 Or, +30 PV) | B13: -25
A14: La Fontaine Bénie — Jeter une pièce dans la fontaine (-20 Or, +8 PV Max) | B14: -20
A15: Le Tombeau Oublié — Piller le sarcophage (+100 Or, -18 PV) | B15: 100
A16: Le Tombeau Oublié — Respecter le repos des morts (+15 Or) | B16: 15
A17: Le Marchand Fugitif — Acheter une relique mystérieuse (-40 Or, +1 Relique) | B17: -40
A18: Le Marchand Fugitif — Voler le gobelin (+50 Or, -12 PV) | B18: 50
A19: L'Autel Mystérieux — Faire une offrande d'or (-50 Or, +10 PV Max) | B19: -50
A20: Le Colporteur — Vendre votre relique la plus faible (+40 à +200 Or selon sa rareté) | B20: 40 × (rang + 1) : 40 / 80 / 120 / 160 / 200
A22: B. Sorties d'or
A23: Carte en boutique | B23: Base | C23: 0 rune | D23: 1 rune | E23: 2 runes | F23: 3 runes | G23: 4 runes
A24: Commune | B24: 25 | C24: =B24+20*0 -> 25 | D24: =B24+20*1 -> 45 | E24: =B24+20*2 -> 65 | F24: =B24+20*3 -> 85 | G24: =B24+20*4 -> 105
A25: Peu commune | B25: 50 | C25: =B25+20*0 -> 50 | D25: =B25+20*1 -> 70 | E25: =B25+20*2 -> 90 | F25: =B25+20*3 -> 110 | G25: =B25+20*4 -> 130
A26: Rare | B26: 100 | C26: =B26+20*0 -> 100 | D26: =B26+20*1 -> 120 | E26: =B26+20*2 -> 140 | F26: =B26+20*3 -> 160 | G26: =B26+20*4 -> 180
A27: Épique | B27: 150 | C27: =B27+20*0 -> 150 | D27: =B27+20*1 -> 170 | E27: =B27+20*2 -> 190 | F27: =B27+20*3 -> 210 | G27: =B27+20*4 -> 230
A28: Légendaire | B28: 200 | C28: =B28+20*0 -> 200 | D28: =B28+20*1 -> 220 | E28: =B28+20*2 -> 240 | F28: =B28+20*3 -> 260 | G28: =B28+20*4 -> 280
A29: Copie du deck : prix de sa rareté sans rune. Carte unique : 999 (jamais en vente).
A30: Service | B30: Prix
A31: Relance de l'étal | B31: 15
A32: Potion (30 % PV max), 1 par boutique | B32: 30
A33: Purge d'une carte | B33: 75
A34: Expansion de l'étal | B34: 100
A35: Miroir magique (n = clonages déjà faits ici) | B35: n = 0 | C35: n = 1 | D35: n = 2 | E35: n = 3 | F35: n = 4
A36: Prix | B36: =150*2^0 -> 150 | C36: =150*2^1 -> 300 | D36: =150*2^2 -> 600 | E36: =150*2^3 -> 1200 | F36: =150*2^4 -> 2400
A38: Affûtage : base b (ForgeRuneRules.sharpenBaseCost) | B38: 50
A39: Puits : base (ForgeRuneRules.wellBaseCost) | B39: 50
A40: Niveau porté L | B40: Affûter L → L+1 | C40: Cumul pour atteindre L depuis 1 | D40: Puits : donner une rune de niveau L | E40: Niveau reçu au Puits
A41: 1 | B41: =$B$38*A41 -> 50 | C41: =$B$38*A41*(A41-1)/2 -> 0 | D41: =$B$39*A41 -> 50 | E41: =INT((2*A41+1)/3) -> 1
A42: 2 | B42: =$B$38*A42 -> 100 | C42: =$B$38*A42*(A42-1)/2 -> 50 | D42: =$B$39*A42 -> 100 | E42: =INT((2*A42+1)/3) -> 1
A43: 3 | B43: =$B$38*A43 -> 150 | C43: =$B$38*A43*(A43-1)/2 -> 150 | D43: =$B$39*A43 -> 150 | E43: =INT((2*A43+1)/3) -> 2
A44: 4 | B44: =$B$38*A44 -> 200 | C44: =$B$38*A44*(A44-1)/2 -> 300 | D44: =$B$39*A44 -> 200 | E44: =INT((2*A44+1)/3) -> 3
...

Sheet Cartes & rareté
A1: Cartes et rareté (règle G1)
A2: CardRarity.scaleValue (lib/models/data/card_data.dart) : à chaque palier, v = max(round(base × mult), v précédent + 1) ; pioche et mana rendu ne grandissent pas (G2) ; le coût ne change jamais
A4: A. Multiplicateurs et rang de fusion
A5: Rareté | B5: Multiplicateur | C5: Rang de fusion | D5: Copies communes nécessaires (3^rang) | E5: Prix boutique (sans rune) | F5: Runes max en boutique
A6: Commune | B6: 1 | C6: 0 | D6: =3^C6 -> 1 | E6: 25 | F6: =C6 -> 0
A7: Peu commune | B7: 1.2 | C7: 1 | D7: =3^C7 -> 3 | E7: 50 | F7: =C7 -> 1
A8: Rare | B8: 1.4 | C8: 2 | D8: =3^C8 -> 9 | E8: 100 | F8: =C8 -> 2
A9: Épique | B9: 1.6 | C9: 3 | D9: =3^C9 -> 27 | E9: 150 | F9: =C9 -> 3
A10: Légendaire | B10: 2 | C10: 4 | D10: =3^C10 -> 81 | E10: 200 | F10: =C10 -> 4
A11: Unique (cartes de classe) | B11: 1 | C11: 0 | D11: jamais de fusion | E11: 999 | F11: 0
A13: B. Une valeur de base à chaque rareté
A14: Base | B14: Commune | C14: Peu commune | D14: Rare | E14: Épique | F14: Légendaire | G14: Gain total (lég. − commune)
A15: 1 | B15: =A15 -> 1 | C15: =MAX(ROUND(A15*$B$7,0),B15+1) -> 2 | D15: =MAX(ROUND(A15*$B$8,0),C15+1) -> 3 | E15: =MAX(ROUND(A15*$B$9,0),D15+1) -> 4 | F15: =MAX(ROUND(A15*$B$10,0),E15+1) -> 5 | G15: =F15-B15 -> 4
A16: 2 | B16: =A16 -> 2 | C16: =MAX(ROUND(A16*$B$7,0),B16+1) -> 3 | D16: =MAX(ROUND(A16*$B$8,0),C16+1) -> 4 | E16: =MAX(ROUND(A16*$B$9,0),D16+1) -> 5 | F16: =MAX(ROUND(A16*$B$10,0),E16+1) -> 6 | G16: =F16-B16 -> 4
A17: 3 | B17: =A17 -> 3 | C17: =MAX(ROUND(A17*$B$7,0),B17+1) -> 4 | D17: =MAX(ROUND(A17*$B$8,0),C17+1) -> 5 | E17: =MAX(ROUND(A17*$B$9,0),D17+1) -> 6 | F17: =MAX(ROUND(A17*$B$10,0),E17+1) -> 7 | G17: =F17-B17 -> 4
A18: 4 | B18: =A18 -> 4 | C18: =MAX(ROUND(A18*$B$7,0),B18+1) -> 5 | D18: =MAX(ROUND(A18*$B$8,0),C18+1) -> 6 | E18: =MAX(ROUND(A18*$B$9,0),D18+1) -> 7 | F18: =MAX(ROUND(A18*$B$10,0),E18+1) -> 8 | G18: =F18-B18 -> 4
A19: 5 | B19: =A19 -> 5 | C19: =MAX(ROUND(A19*$B$7,0),B19+1) -> 6 | D19: =MAX(ROUND(A19*$B$8,0),C19+1) -> 7 | E19: =MAX(ROUND(A19*$B$9,0),D19+1) -> 8 | F19: =MAX(ROUND(A19*$B$10,0),E19+1) -> 10 | G19: =F19-B19 -> 5
A20: 6 | B20: =A20 -> 6 | C20: =MAX(ROUND(A20*$B$7,0),B20+1) -> 7 | D20: =MAX(ROUND(A20*$B$8,0),C20+1) -> 8 | E20: =MAX(ROUND(A20*$B$9,0),D20+1) -> 10 | F20: =MAX(ROUND(A20*$B$10,0),E20+1) -> 12 | G20: =F20-B20 -> 6
A21: 7 | B21: =A21 -> 7 | C21: =MAX(ROUND(A21*$B$7,0),B21+1) -> 8 | D21: =MAX(ROUND(A21*$B$8,0),C21+1) -> 10 | E21: =MAX(ROUND(A21*$B$9,0),D21+1) -> 11 | F21: =MAX(ROUND(A21*$B$10,0),E21+1) -> 14 | G21: =F21-B21 -> 7
A22: 8 | B22: =A22 -> 8 | C22: =MAX(ROUND(A22*$B$7,0),B22+1) -> 10 | D22: =MAX(ROUND(A22*$B$8,0),C22+1) -> 11 | E22: =MAX(ROUND(A22*$B$9,0),D22+1) -> 13 | F22: =MAX(ROUND(A22*$B$10,0),E22+1) -> 16 | G22: =F22-B22 -> 8
A23: 9 | B23: =A23 -> 9 | C23: =MAX(ROUND(A23*$B$7,0),B23+1) -> 11 | D23: =MAX(ROUND(A23*$B$8,0),C23+1) -> 13 | E23: =MAX(ROUND(A23*$B$9,0),D23+1) -> 14 | F23: =MAX(ROUND(A23*$B$10,0),E23+1) -> 18 | G23: =F23-B23 -> 9
A24: 10 | B24: =A24 -> 10 | C24: =MAX(ROUND(A24*$B$7,0),B24+1) -> 12 | D24: =MAX(ROUND(A24*$B$8,0),C24+1) -> 14 | E24: =MAX(ROUND(A24*$B$9,0),D24+1) -> 16 | F24: =MAX(ROUND(A24*$B$10,0),E24+1) -> 20 | G24: =F24-B24 -> 10
A25: 11 | B25: =A25 -> 11 | C25: =MAX(ROUND(A25*$B$7,0),B25+1) -> 13 | D25: =MAX(ROUND(A25*$B$8,0),C25+1) -> 15 | E25: =MAX(ROUND(A25*$B$9,0),D25+1) -> 18 | F25: =MAX(ROUND(A25*$B$10,0),E25+1) -> 22 | G25: =F25-B25 -> 11
A26: 12 | B26: =A26 -> 12 | C26: =MAX(ROUND(A26*$B$7,0),B26+1) -> 14 | D26: =MAX(ROUND(A26*$B$8,0),C26+1) -> 17 | E26: =MAX(ROUND(A26*$B$9,0),D26+1) -> 19 | F26: =MAX(ROUND(A26*$B$10,0),E26+1) -> 24 | G26: =F26-B26 -> 12
... A34: 20 | B34: =A34 -> 20 | C34: =MAX(ROUND(A34*$B$7,0),B34+1) -> 24 | D34: =MAX(ROUND(A34*$B$8,0),C34+1) -> 28 | E34: =MAX(ROUND(A34*$B$9,0),D34+1) -> 32 | F34: =MAX(ROUND(A34*$B$10,0),E34+1) -> 40 | G34: =F34-B34 -> 20
A35: Base 1 : 1 · 2 · 3 · 4 · 5 (le « au moins +1 » joue). Base 5 : 5 · 6 · 7 · 8 · 10. Base 12 : 12 · 14 · 17 · 19 · 24.
A37: C. Les 23 cartes, effet par effet
A38: Carte | B38: Type | C38: Coût | D38: Rareté | E38: Effet | F38: Base | G38: Commune | H38: Peu commune | I38: Rare | J38: Épique | K38: Légendaire | L38: Note
A39: Éveil | B39: Compétence | C39: 1 | D39: Commune | E39: armor | F39: 4 | G39: =F39 -> 4 | H39: =MAX(ROUND(F39*$B$7,0),G39+1) -> 5 | I39: =MAX(ROUND(F39*$B$8,0),H39+1) -> 6 | J39: =MAX(ROUND(F39*$B$9,0),I39+1) -> 7 | K39: =MAX(ROUND(F39*$B$10,0),J39+1) -> 8
E40: draw | F40: 1 | G40: =F40 -> 1 | H40: =F40 -> 1 | I40: =F40 -> 1 | J40: =F40 -> 1 | K40: =F40 -> 1 | L40: G2 : gelé par la rareté
A41: Concentration | B41: Compétence | C41: 0 | D41: Commune | E41: draw | F41: 2 | G41: =F41 -> 2 | H41: =F41 -> 2 | I41: =F41 -> 2 | J41: =F41 -> 2 | K41: =F41 -> 2 | L41: G2 : gelé par la rareté
A42: Défense | B42: Compétence | C42: 1 | D42: Commune | E42: armor | F42: 5 | G42: =F42 -> 5 | H42: =MAX(ROUND(F42*$B$7,0),G42+1) -> 6 | I42: =MAX(ROUND(F42*$B$8,0),H42+1) -> 7 | J42: =MAX(ROUND(F42*$B$9,0),I42+1) -> 8 | K42: =MAX(ROUND(F42*$B$10,0),J42+1) -> 10
A43: Forme Démoniaque | B43: Pouvoir | C43: 2 | D43: Commune | E43: apply_status (might, 4 t.) | F43: 2 | G43: =F43 -> 2 | H43: =MAX(ROUND(F43*$B$7,0),G43+1) -> 3 | I43: =MAX(ROUND(F43*$B$8,0),H43+1) -> 4 | J43: =MAX(ROUND(F43*$B$9,0),I43+1) -> 5 | K43: =MAX(ROUND(F43*$B$10,0),J43+1) -> 6
A44: Boule de Feu | B44: Attaque | C44: 2 | D44: Commune | E44: damage | F44: 6 | G44: =F44 -> 6 | H44: =MAX(ROUND(F44*$B$7,0),G44+1) -> 7 | I44: =MAX(ROUND(F44*$B$8,0),H44+1) -> 8 | J44: =MAX(ROUND(F44*$B$9,0),I44+1) -> 10 | K44: =MAX(ROUND(F44*$B$10,0),J44+1) -> 12
E45: apply_status (burn, 2 t.) | F45: 2 | G45: =F45 -> 2 | H45: =MAX(ROUND(F45*$B$7,0),G45+1) -> 3 | I45: =MAX(ROUND(F45*$B$8,0),H45+1) -> 4 | J45: =MAX(ROUND(F45*$B$9,0),I45+1) -> 5 | K45: =MAX(ROUND(F45*$B$10,0),J45+1) -> 6
A46: Focalisation | B46: Compétence | C46: 0 | D46: Commune | E46: gain_mana | F46: 1 | G46: =F46 -> 1 | H46: =F46 -> 1 | I46: =F46 -> 1 | J46: =F46 -> 1 | K46: =F46 -> 1 | L46: G2 : gelé par la rareté
A47: Potion de Soin | B47: Compétence | C47: 1 | D47: Commune | E47: heal | F47: 3 | G47: =F47 -> 3 | H47: =MAX(ROUND(F47*$B$7,0),G47+1) -> 4 | I47: =MAX(ROUND(F47*$B$8,0),H47+1) -> 5 | J47: =MAX(ROUND(F47*$B$9,0),I47+1) -> 6 | K47: =MAX(ROUND(F47*$B$10,0),J47+1) -> 7
A48: Frappe Lourde | B48: Attaque | C48: 2 | D48: Commune | E48: damage | F48: 12 | G48: =F48 -> 12 | H48: =MAX(ROUND(F48*$B$7,0),G48+1) -> 14 | I48: =MAX(ROUND(F48*$B$8,0),H48+1) -> 17 | J48: =MAX(ROUND(F48*$B$9,0),I48+1) -> 19 | K48: =MAX(ROUND(F48*$B$10,0),J48+1) -> 24
A49: Trait de Glace | B49: Attaque | C49: 1 | D49: Commune | E49: damage | F49: 4 | G49: =F49 -> 4 | H49: =MAX(ROUND(F49*$B$7,0),G49+1) -> 5 | I49: =MAX(ROUND(F49*$B$8,0),H49+1) -> 6 | J49: =MAX(ROUND(F49*$B$9,0),I49+1) -> 7 | K49: =MAX(ROUND(F49*$B$10,0),J49+1) -> 8
E50: apply_status (freeze, 1 t.) | F50: 1 | G50: =F50 -> 1 | H50: =MAX(ROUND(F50*$B$7,0),G50+1) -> 2 | I50: =MAX(ROUND(F50*$B$8,0),H50+1) -> 3 | J50: =MAX(ROUND(F50*$B$9,0),I50+1) -> 4 | K50: =MAX(ROUND(F50*$B$10,0),J50+1) -> 5
...

Sheet Runes (valeurs)
A1: Les runes : ce qu'elles ajoutent
A2: CardDelta (lib/models/data/card_delta.dart) + EffectiveCard.apply ; bonus en % = max((p × L × B + 50) ÷ 100 entier, L)
A4: A. Catalogue
A5: Rune | B5: Delta | C5: Par niveau | D5: Plafond | E5: Rang min | L5: Effet
A6: Brûlant | B6: addEffect | C6: 1 | D6: aucun | E6: 1 | L6: Applique {val} Brûlure
A7: Allégé | B7: reduceCost | C7: 1 | D7: 1 | E7: 1 | L7: Coûte {val} Mana de moins (jamais sous 0)
A8: Économe | B8: addEffect | C8: 1 | D8: 1 | E8: 2 | L8: Gagne +{val} Mana à l'utilisation
A9: Persistant | B9: removeExhaust | D9: 1 | E9: 1 | L9: Retire Épuisement (Exhaust)
A10: Congelant | B10: addEffect | C10: 1 | D10: 1 | E10: 1 | L10: Applique {val} Gel
A11: Endurci | B11: percentBonus | C11: 15 | D11: aucun | E11: 1 | L11: +{val} Armure sur la carte (+{percent}% de la base, au moins +{tier})
A12: Précis | B12: critBonus | C12: 5 | D12: 10 | E12: 1 | L12: +{val}% de chance de critique sur les dégâts de la carte
A13: Véloce | B13: addEffect | C13: 1 | D13: 1 | E13: 2 | L13: Pioche +{val} carte(s)
A14: Tranchant | B14: percentBonus | C14: 15 | D14: aucun | E14: 1 | L14: +{val} Dégâts sur la carte (+{percent}% de la base, au moins +{tier})
A15: Surchargé | B15: addEffect | C15: 1 | D15: aucun | E15: 1 | L15: Applique {val} Électrocution
A16: Spectral | B16: percentBonus | C16: 40 | D16: aucun | E16: 1 | L16: +{val} Dégâts sur la carte (+{percent}% de la base, au moins +{tier}) ; la carte s'épuise
A18: B. Bonus en pourcentage (Tranchant, Endurci : 15 % ; Spectral : 40 %) sur la valeur à la rareté B
A19: p (Tranchant / Endurci) | B19: 15
A20: p (Spectral) | B20: 40
A21: B (valeur à la rareté) | B21: L = 1 (15 %) | C21: L = 2 (15 %) | D21: L = 3 (15 %) | E21: L = 4 (15 %) | F21: L = 5 (15 %) | G21: L = 1 (40 %) | H21: L = 2 (40 %) | I21: L = 3 (40 %) | J21: L = 4 (40 %) | K21: L = 5 (40 %) | L21: Note
A22: 1 | B22: =MAX(INT(($B$19*1*A22+50)/100),1) -> 1 | C22: =MAX(INT(($B$19*2*A22+50)/100),2) -> 2 | D22: =MAX(INT(($B$19*3*A22+50)/100),3) -> 3 | E22: =MAX(INT(($B$19*4*A22+50)/100),4) -> 4 | F22: =MAX(INT(($B$19*5*A22+50)/100),5) -> 5 | G22: =MAX(INT(($B$20*1*A22+50)/100),1) -> 1 | H22: =MAX(INT(($B$20*2*A22+50)/100),2) -> 2 | I22: =MAX(INT(($B$20*3*A22+50)/100),3) -> 3 | J22: =MAX(INT(($B$20*4*A22+50)/100),4) -> 4 | K22: =MAX(INT(($B$20*5*A22+50)/100),5) -> 5
A23: 2 | B23: =MAX(INT(($B$19*1*A23+50)/100),1) -> 1 | C23: =MAX(INT(($B$19*2*A23+50)/100),2) -> 2 | D23: =MAX(INT(($B$19*3*A23+50)/100),3) -> 3 | E23: =MAX(INT(($B$19*4*A23+50)/100),4) -> 4 | F23: =MAX(INT(($B$19*5*A23+50)/100),5) -> 5 | G23: =MAX(INT(($B$20*1*A23+50)/100),1) -> 1 | H23: =MAX(INT(($B$20*2*A23+50)/100),2) -> 2 | I23: =MAX(INT(($B$20*3*A23+50)/100),3) -> 3 | J23: =MAX(INT(($B$20*4*A23+50)/100),4) -> 4 | K23: =MAX(INT(($B$20*5*A23+50)/100),5) -> 5
A24: 3 | B24: =MAX(INT(($B$19*1*A24+50)/100),1) -> 1 | C24: =MAX(INT(($B$19*2*A24+50)/100),2) -> 2 | D24: =MAX(INT(($B$19*3*A24+50)/100),3) -> 3 | E24: =MAX(INT(($B$19*4*A24+50)/100),4) -> 4 | F24: =MAX(INT(($B$19*5*A24+50)/100),5) -> 5 | G24: =MAX(INT(($B$20*1*A24+50)/100),1) -> 1 | H24: =MAX(INT(($B$20*2*A24+50)/100),2) -> 2 | I24: =MAX(INT(($B$20*3*A24+50)/100),3) -> 4 | J24: =MAX(INT(($B$20*4*A24+50)/100),4) -> 5 | K24: =MAX(INT(($B$20*5*A24+50)/100),5) -> 6
A25: 4 | B25: =MAX(INT(($B$19*1*A25+50)/100),1) -> 1 | C25: =MAX(INT(($B$19*2*A25+50)/100),2) -> 2 | D25: =MAX(INT(($B$19*3*A25+50)/100),3) -> 3 | E25: =MAX(INT(($B$19*4*A25+50)/100),4) -> 4 | F25: =MAX(INT(($B$19*5*A25+50)/100),5) -> 5 | G25: =MAX(INT(($B$20*1*A25+50)/100),1) -> 2 | H25: =MAX(INT(($B$20*2*A25+50)/100),2) -> 3 | I25: =MAX(INT(($B$20*3*A25+50)/100),3) -> 5 | J25: =MAX(INT(($B$20*4*A25+50)/100),4) -> 6 | K25: =MAX(INT(($B$20*5*A25+50)/100),5) -> 8
A26: 5 | B26: =MAX(INT(($B$19*1*A26+50)/100),1) -> 1 | C26: =MAX(INT(($B$19*2*A26+50)/100),2) -> 2 | D26: =MAX(INT(($B$19*3*A26+50)/100),3) -> 3 | E26: =MAX(INT(($B$19*4*A26+50)/100),4) -> 4 | F26: =MAX(INT(($B$19*5*A26+50)/100),5) -> 5 | G26: =MAX(INT(($B$20*1*A26+50)/100),1) -> 2 | H26: =MAX(INT(($B$20*2*A26+50)/100),2) -> 4 | I26: =MAX(INT(($B$20*3*A26+50)/100),3) -> 6 | J26: =MAX(INT(($B$20*4*A26+50)/100),4) -> 8 | K26: =MAX(INT(($B$20*5*A26+50)/100),5) -> 10
A27: 6 | B27: =MAX(INT(($B$19*1*A27+50)/100),1) -> 1 | C27: =MAX(INT(($B$19*2*A27+50)/100),2) -> 2 | D27: =MAX(INT(($B$19*3*A27+50)/100),3) -> 3 | E27: =MAX(INT(($B$19*4*A27+50)/100),4) -> 4 | F27: =MAX(INT(($B$19*5*A27+50)/100),5) -> 5 | G27: =MAX(INT(($B$20*1*A27+50)/100),1) -> 2 | H27: =MAX(INT(($B$20*2*A27+50)/100),2) -> 5 | I27: =MAX(INT(($B$20*3*A27+50)/100),3) -> 7 | J27: =MAX(INT(($B$20*4*A27+50)/100),4) -> 10 | K27: =MAX(INT(($B$20*5*A27+50)/100),5) -> 12
A28: 7 | B28: =MAX(INT(($B$19*1*A28+50)/100),1) -> 1 | C28: =MAX(INT(($B$19*2*A28+50)/100),2) -> 2 | D28: =MAX(INT(($B$19*3*A28+50)/100),3) -> 3 | E28: =MAX(INT(($B$19*4*A28+50)/100),4) -> 4 | F28: =MAX(INT(($B$19*5*A28+50)/100),5) -> 5 | G28: =MAX(INT(($B$20*1*A28+50)/100),1) -> 3 | H28: =MAX(INT(($B$20*2*A28+50)/100),2) -> 6 | I28: =MAX(INT(($B$20*3*A28+50)/100),3) -> 8 | J28: =MAX(INT(($B$20*4*A28+50)/100),4) -> 11 | K28: =MAX(INT(($B$20*5*A28+50)/100),5) -> 14
A29: 8 | B29: =MAX(INT(($B$19*1*A29+50)/100),1) -> 1 | C29: =MAX(INT(($B$19*2*A29+50)/100),2) -> 2 | D29: =MAX(INT(($B$19*3*A29+50)/100),3) -> 4 | E29: =MAX(INT(($B$19*4*A29+50)/100),4) -> 5 | F29: =MAX(INT(($B$19*5*A29+50)/100),5) -> 6 | G29: =MAX(INT(($B$20*1*A29+50)/100),1) -> 3 | H29: =MAX(INT(($B$20*2*A29+50)/100),2) -> 6 | I29: =MAX(INT(($B$20*3*A29+50)/100),3) -> 10 | J29: =MAX(INT(($B$20*4*A29+50)/100),4) -> 13 | K29: =MAX(INT(($B$20*5*A29+50)/100),5) -> 16
