Workbook

Sheet Lisez-moi
A1: Hero's Draft — Toutes les probabilités du jeu
A2: Version du jeu : 0.5.5 (branche main, commit 0ec09ab, lue le 13/10/2026). Un onglet par système de tirage.
A4: Comment lire ce classeur
A5: Texte bleu | B5: Valeur lue telle quelle dans le code Dart ou dans un fichier JSON de assets/data/. Modifiable pour tester un changement d'équilibrage.
A6: Texte bleu sur fond jaune | B6: Paramètre de scénario (acte, Chance, taille de deck…) : à saisir pour explorer un cas.
A7: Texte noir | B7: Formule : se recalcule quand une entrée change.
A8: Texte vert | B8: Lien vers un autre onglet de ce classeur.
A9: Probabilités | B9: Toujours stockées en fraction (0,25 = 25 %). Les poids « en points » du code (ex. 2 + 0,5 × Chance) sont gardés en points, la colonne de probabilité les convertit.
A10: Ligne « Source » | B10: Fichier et fonction du dépôt où vit la règle. Toute valeur du classeur a été relue dans ce fichier le 13/10/2026.
A11: Valeurs figées | B11: Quelques cellules (tirage de 3 runes sans remise) sont calculées par énumération en Python et notées comme telles : une formule Excel ne sait pas les écrire.
A13: Les onglets
A14: Onglet | B14: Contenu
A15: Carte | B15: Génération de la carte du monde : type des nœuds, largeur des étages, quotas, connexions, Autel et Puits.
A16: Niveau (draft) | B16: Récompenses de montée de niveau : rareté des trois emplacements selon la Chance, mythiques, choix proposés.
A17: Reliques | B17: Butin de reliques : élite et événement, relique améliorée du boss, Autel d'échange, Colporteur, pool par rareté.
A18: Trouvaille | B18: Cartes trouvées après un combat : combat normal, élite, reliques qui modulent, pool de 17 neutres, copies cumulées.
A19: Boutique | B19: Étal : rareté selon l'acte, runes pré-forgées, niveau des runes, tirage de l'étal, copie du deck, prix.
A20: Runes | B20: Tirage pondéré des runes à la fusion et en boutique, carte par carte, au rang 1 et au rang 2+.
A21: Critique | B21: Coup critique : chances par classe, ennemi, relique, rune et récompense ; multiplicateur attendu.
A22: Rencontres | B22: Composition d'un combat : tiers débloqués, nombre maximal d'ennemis, tirage uniforme parmi les candidats qui tiennent dans le budget, calculateur.
A23: Événements | B23: Sept événements à parts égales, chances cumulées, choix et conditions.
A24: Pioche | B24: Main d'ouverture et pioche : loi hypergéométrique, cartes vues au tour t, remélange.
A25: Boss & Miroirs | B25: Récompenses de boss et clonages : cartes tirées dans le deck, rune montée par le boss d'XP.
A26: Chance (synthèse) | B26: Tout ce que la statistique Chance modifie, sur une seule page.
A28: Les systèmes sans aucun tirage (prix, courbe d'XP, difficulté par acte, valeurs des cartes et des runes) sont dans le second classeur : 2026-10-13_systemes_et_calculs.xlsx.

Sheet Carte
A1: Génération de la carte du monde
A2: MapGeneratorService.generateMap(floors: 10, maxWidth: 5, act) — lib/services/map/*.dart
A4: A. Type d'un nœud sur un étage libre (étages 1-4 et 6-7)
A5: Source : lib/services/map/map_node_generator.dart, getRandomNodeType : r = nextDouble(), seuils cumulés
A6: Type | B6: Seuil cumulé (r <) | C6: Probabilité | I6: Note
A7: Combat | B7: 0.6 | C7: =B7 -> 0.6 | I7: L'étage 0 est 100 % combat : aucun tirage.
A8: Événement | B8: 0.75 | C8: =B8-B7 -> 0.15
A9: Boutique | B9: 0.85 | C9: =B9-B8 -> 0.1
A10: Repos | B10: 0.95 | C10: =B10-B9 -> 0.1
A11: Élite | B11: 1 | C11: =B11-B10 -> 0.05
A12: Total | C12: =SUM(C7:C11) -> 1
A14: B. Largeur d'un étage
A15: Source : map_node_generator.dart : rowWidth = 2 + nextInt(maxWidth - 1) → uniforme de 2 à maxWidth
A16: maxWidth | B16: 5
A17: Largeur | B17: Probabilité
A18: 2 | B18: =IF(2<=$B$16,1/($B$16-1),0) -> 0.25
A19: 3 | B19: =IF(3<=$B$16,1/($B$16-1),0) -> 0.25
A20: 4 | B20: =IF(4<=$B$16,1/($B$16-1),0) -> 0.25
A21: 5 | B21: =IF(5<=$B$16,1/($B$16-1),0) -> 0.25
A22: Largeur attendue E[w] | B22: =SUMPRODUCT(A18:A21,B18:B21) -> 3.5
A24: C. Étages à règle fixe (10 étages, 0 à 9)
A25: Source : map_node_generator.dart generateRawNodes : middleFloor = floors ~/ 2 ; étage floors-2 repos ; étage floors-1 trois boss
A26: Étage | B26: Largeur | C26: Type imposé | D26: Récompense de boss (x = 0 / 1 / 2)
A27: 0 | B27: 2 à 5 | C27: Combat (entrée)
A28: 1-4, 6-7 | B28: 2 à 5 | C28: Tirage de la section A
A29: 5 | B29: 1 | C29: Élite (goulet)
A30: 8 | B30: 2 à 5 | C30: Repos
A31: 9 | B31: 3 | C31: Boss | D31: Cartes (x=0) / XP triple + rune montée (x=1) / Relique améliorée (x=2) — choix du joueur, pas de tirage
A33: D. Nombre attendu de nœuds par type, avant le solveur de quotas
A34: Source : GameConstants.nodeQuotas (lib/game/game_constants.dart) ; MapValidator.balanceQuotas convertit des nœuds jusqu'à respecter min et max
A35: Étages libres (tirés) | B35: 6 | C35: étages 1, 2, 3, 4, 6, 7
A36: Nœuds tirés au hasard E[n] | B36: =$B$35*$B$22 -> 21 | C36: soit étages libres × largeur attendue
A37: Type | B37: Attendu (tirage) | C37: Quota min | D37: Quota max | E37: Sous le min ? | I37: Lecture
A38: Combat | B38: =$B$36*$C$7+$B$22 -> 16.1 | C38: 12 | D38: 22 | E38: =IF(B38<C38,"oui","non") -> non | I38: l'étage 0 ajoute E[w] combats
A39: Élite | B39: =$B$36*$C$11+1 -> 2.05 | C39: 3 | D39: 6 | E39: =IF(B39<C39,"oui","non") -> oui | I39: le goulet ajoute 1 élite
A40: Repos | B40: =$B$36*$C$10+$B$22 -> 5.6 | C40: 3 | D40: 6 | E40: =IF(B40<C40,"oui","non") -> non | I40: l'étage 8 ajoute E[w] repos
A41: Boutique | B41: =$B$36*$C$9 -> 2.1 | C41: 2 | D41: 5 | E41: =IF(B41<C41,"oui","non") -> non
A42: Événement | B42: =$B$36*$C$8 -> 3.15 | C42: 4 | D42: 9 | E42: =IF(B42<C42,"oui","non") -> oui | I42: attendu sous le min : le solveur relève, les événements sont plus fréquents que 15 %
A43: Boss | B43: 3 | C43: 3 | D43: 3 | E43: =IF(B43<C43,"oui","non") -> non
A44: Total attendu | B44: =SUM(B38:B43) -> 32
...

Sheet Niveau (draft)
A1: Récompenses de montée de niveau
A2: LevelUpRewardService (lib/game/services/level_up_reward_service.dart) — trois emplacements tirés + un jet par mythique
A4: A. Poids de rareté d'un emplacement (en points de %, selon la Chance)
A5: Source : LevelUpRewardService._slotWeights : légendaire 2 + 0,5 L ; épique 6 + 1,5 L ; rare 16 + 3 L ; peu commune 24 + 4 L ; commune = le reste. slotRarityChances borne chaque poids entre 0 et ce qui reste de 100.
A6: Rareté | B6: Base (pts) | C6: Par point de Chance
A7: Légendaire | B7: 2 | C7: 0.5
A8: Épique | B8: 6 | C8: 1.5
A9: Rare | B9: 16 | C9: 3
A10: Peu commune | B10: 24 | C10: 4
A12: B. Probabilité de chaque rareté pour UN emplacement, par niveau de Chance
A13: Chance | B13: Légendaire | C13: Épique | D13: Rare | E13: Peu commune | F13: Commune | G13: Rare ou mieux | H13: P(≥1 légendaire sur 3) | I13: P(≥1 épique+ sur 3) | J13: Espérance d'emplacements rare+ (sur 3)
A14: 0 | B14: =MAX(0,MIN($B$7+$C$7*A14,100))/100 -> 0.02 | C14: =MAX(0,MIN($B$8+$C$8*A14,100-100*B14))/100 -> 0.06 | D14: =MAX(0,MIN($B$9+$C$9*A14,100-100*(B14+C14)))/100 -> 0.16 | E14: =MAX(0,MIN($B$10+$C$10*A14,100-100*(B14+C14+D14)))/100 -> 0.24 | F14: =1-SUM(B14:E14) -> 0.52 | G14: =SUM(B14:D14) -> 0.24 | H14: =1-(1-B14)^3 -> 0.058808 | I14: =1-(1-B14-C14)^3 -> 0.221312 | J14: =3*G14 -> 0.72
A15: 1 | B15: =MAX(0,MIN($B$7+$C$7*A15,100))/100 -> 0.025 | C15: =MAX(0,MIN($B$8+$C$8*A15,100-100*B15))/100 -> 0.075 | D15: =MAX(0,MIN($B$9+$C$9*A15,100-100*(B15+C15)))/100 -> 0.19 | E15: =MAX(0,MIN($B$10+$C$10*A15,100-100*(B15+C15+D15)))/100 -> 0.28 | F15: =1-SUM(B15:E15) -> 0.43 | G15: =SUM(B15:D15) -> 0.29 | H15: =1-(1-B15)^3 -> 0.073140625 | I15: =1-(1-B15-C15)^3 -> 0.271 | J15: =3*G15 -> 0.87
A16: 2 | B16: =MAX(0,MIN($B$7+$C$7*A16,100))/100 -> 0.03 | C16: =MAX(0,MIN($B$8+$C$8*A16,100-100*B16))/100 -> 0.09 | D16: =MAX(0,MIN($B$9+$C$9*A16,100-100*(B16+C16)))/100 -> 0.22 | E16: =MAX(0,MIN($B$10+$C$10*A16,100-100*(B16+C16+D16)))/100 -> 0.32 | F16: =1-SUM(B16:E16) -> 0.34 | G16: =SUM(B16:D16) -> 0.34 | H16: =1-(1-B16)^3 -> 0.087327 | I16: =1-(1-B16-C16)^3 -> 0.318528 | J16: =3*G16 -> 1.02
A17: 3 | B17: =MAX(0,MIN($B$7+$C$7*A17,100))/100 -> 0.035 | C17: =MAX(0,MIN($B$8+$C$8*A17,100-100*B17))/100 -> 0.105 | D17: =MAX(0,MIN($B$9+$C$9*A17,100-100*(B17+C17)))/100 -> 0.25 | E17: =MAX(0,MIN($B$10+$C$10*A17,100-100*(B17+C17+D17)))/100 -> 0.36 | F17: =1-SUM(B17:E17) -> 0.25 | G17: =SUM(B17:D17) -> 0.39 | H17: =1-(1-B17)^3 -> 0.10136788 | I17: =1-(1-B17-C17)^3 -> 0.363944 | J17: =3*G17 -> 1.17
A18: 4 | B18: =MAX(0,MIN($B$7+$C$7*A18,100))/100 -> 0.04 | C18: =MAX(0,MIN($B$8+$C$8*A18,100-100*B18))/100 -> 0.12 | D18: =MAX(0,MIN($B$9+$C$9*A18,100-100*(B18+C18)))/100 -> 0.28 | E18: =MAX(0,MIN($B$10+$C$10*A18,100-100*(B18+C18+D18)))/100 -> 0.4 | F18: =1-SUM(B18:E18) -> 0.16 | G18: =SUM(B18:D18) -> 0.44 | H18: =1-(1-B18)^3 -> 0.115264 | I18: =1-(1-B18-C18)^3 -> 0.407296 | J18: =3*G18 -> 1.32
A19: 5 | B19: =MAX(0,MIN($B$7+$C$7*A19,100))/100 -> 0.045 | C19: =MAX(0,MIN($B$8+$C$8*A19,100-100*B19))/100 -> 0.135 | D19: =MAX(0,MIN($B$9+$C$9*A19,100-100*(B19+C19)))/100 -> 0.31 | E19: =MAX(0,MIN($B$10+$C$10*A19,100-100*(B19+C19+D19)))/100 -> 0.44 | F19: =1-SUM(B19:E19) -> 0.07 | G19: =SUM(B19:D19) -> 0.49 | H19: =1-(1-B19)^3 -> 0.12901613 | I19: =1-(1-B19-C19)^3 -> 0.448632 | J19: =3*G19 -> 1.47
A20: 6 | B20: =MAX(0,MIN($B$7+$C$7*A20,100))/100 -> 0.05 | C20: =MAX(0,MIN($B$8+$C$8*A20,100-100*B20))/100 -> 0.15 | D20: =MAX(0,MIN($B$9+$C$9*A20,100-100*(B20+C20)))/100 -> 0.34 | E20: =MAX(0,MIN($B$10+$C$10*A20,100-100*(B20+C20+D20)))/100 -> 0.46 | F20: =1-SUM(B20:E20) -> 0 | G20: =SUM(B20:D20) -> 0.54 | H20: =1-(1-B20)^3 -> 0.142625 | I20: =1-(1-B20-C20)^3 -> 0.488 | J20: =3*G20 -> 1.62
A21: 7 | B21: =MAX(0,MIN($B$7+$C$7*A21,100))/100 -> 0.055 | C21: =MAX(0,MIN($B$8+$C$8*A21,100-100*B21))/100 -> 0.165 | D21: =MAX(0,MIN($B$9+$C$9*A21,100-100*(B21+C21)))/100 -> 0.37 | E21: =MAX(0,MIN($B$10+$C$10*A21,100-100*(B21+C21+D21)))/100 -> 0.41 | F21: =1-SUM(B21:E21) -> 0 | G21: =SUM(B21:D21) -> 0.59 | H21: =1-(1-B21)^3 -> 0.15609138 | I21: =1-(1-B21-C21)^3 -> 0.525448 | J21: =3*G21 -> 1.77
A22: 8 | B22: =MAX(0,MIN($B$7+$C$7*A22,100))/100 -> 0.06 | C22: =MAX(0,MIN($B$8+$C$8*A22,100-100*B22))/100 -> 0.18 | D22: =MAX(0,MIN($B$9+$C$9*A22,100-100*(B22+C22)))/100 -> 0.4 | E22: =MAX(0,MIN($B$10+$C$10*A22,100-100*(B22+C22+D22)))/100 -> 0.36 | F22: =1-SUM(B22:E22) -> 0 | G22: =SUM(B22:D22) -> 0.64 | H22: =1-(1-B22)^3 -> 0.169416 | I22: =1-(1-B22-C22)^3 -> 0.561024 | J22: =3*G22 -> 1.92
A23: 9 | B23: =MAX(0,MIN($B$7+$C$7*A23,100))/100 -> 0.065 | C23: =MAX(0,MIN($B$8+$C$8*A23,100-100*B23))/100 -> 0.195 | D23: =MAX(0,MIN($B$9+$C$9*A23,100-100*(B23+C23)))/100 -> 0.43 | E23: =MAX(0,MIN($B$10+$C$10*A23,100-100*(B23+C23+D23)))/100 -> 0.31 | F23: =1-SUM(B23:E23) -> 0 | G23: =SUM(B23:D23) -> 0.69 | H23: =1-(1-B23)^3 -> 0.18259962 | I23: =1-(1-B23-C23)^3 -> 0.594776 | J23: =3*G23 -> 2.07
A24: 10 | B24: =MAX(0,MIN($B$7+$C$7*A24,100))/100 -> 0.07 | C24: =MAX(0,MIN($B$8+$C$8*A24,100-100*B24))/100 -> 0.21 | D24: =MAX(0,MIN($B$9+$C$9*A24,100-100*(B24+C24)))/100 -> 0.46 | E24: =MAX(0,MIN($B$10+$C$10*A24,100-100*(B24+C24+D24)))/100 -> 0.26 | F24: =1-SUM(B24:E24) -> 0 | G24: =SUM(B24:D24) -> 0.74 | H24: =1-(1-B24)^3 -> 0.195643 | I24: =1-(1-B24-C24)^3 -> 0.626752 | J24: =3*G24 -> 2.22
A25: 11 | B25: =MAX(0,MIN($B$7+$C$7*A25,100))/100 -> 0.075 | C25: =MAX(0,MIN($B$8+$C$8*A25,100-100*B25))/100 -> 0.225 | D25: =MAX(0,MIN($B$9+$C$9*A25,100-100*(B25+C25)))/100 -> 0.49 | E25: =MAX(0,MIN($B$10+$C$10*A25,100-100*(B25+C25+D25)))/100 -> 0.21 | F25: =1-SUM(B25:E25) -> 0 | G25: =SUM(B25:D25) -> 0.79 | H25: =1-(1-B25)^3 -> 0.20854687 | I25: =1-(1-B25-C25)^3 -> 0.657 | J25: =3*G25 -> 2.37
A26: 12 | B26: =MAX(0,MIN($B$7+$C$7*A26,100))/100 -> 0.08 | C26: =MAX(0,MIN($B$8+$C$8*A26,100-100*B26))/100 -> 0.24 | D26: =MAX(0,MIN($B$9+$C$9*A26,100-100*(B26+C26)))/100 -> 0.52 | E26: =MAX(0,MIN($B$10+$C$10*A26,100-100*(B26+C26+D26)))/100 -> 0.16 | F26: =1-SUM(B26:E26) -> 0 | G26: =SUM(B26:D26) -> 0.84 | H26: =1-(1-B26)^3 -> 0.221312 | I26: =1-(1-B26-C26)^3 -> 0.685568 | J26: =3*G26 -> 2.52
A27: Chance 0 : 2 / 6 / 16 / 24 / 52 %. La fiche des probabilités en jeu (ProbabilitiesDialog) lit la même table.
A29: C. Quelle récompense dans un emplacement ?
A30: Source : generateChoices : chaque emplacement tire uniformément une récompense du pool « draft » (rareté tirée séparément) ; Affinité se retire si le passif actif n'a pas de bloc mastery (les 9 passifs livrés en ont un)
A31: Récompenses tirables (pool draft) | B31: 5 | C31: Affinité, Férocité, Précision, Aiguisage, Vitalité
A32: P(une récompense donnée dans 1 emplacement) | B32: =1/$B$31 -> 0.2
A33: P(une récompense donnée apparaît au moins 1 fois sur 3) | B33: =1-(1-1/$B$31)^3 -> 0.488
A34: P(les 3 emplacements proposent la même) | B34: =$B$31*(1/$B$31)^3 -> 0.04
A35: P(trois récompenses différentes) | B35: =($B$31*($B$31-1)*($B$31-2))/$B$31^3 -> 0.48
A37: D. Les mythiques : un jet indépendant par récompense « mythic »
A38: Source : rollRarity(isLevelReward: true) : mythicChance = 0,5 + 0,15 × Chance (en points) ; un jet par mythique éligible, ajoutée aux trois emplacements
A39: Base (pts) | B39: 0.5
A40: Par point de Chance (pts) | B40: 0.15
A41: Mythiques toujours éligibles | B41: 3 | C41: Trèfle à 4 feuilles, Miroir, Sagesse
A42: Mythiques conditionnelles | B42: 1 | C42: Transcendance (requires: raisableRune)
A43: Chance | B43: p (par mythique) | C43: P(≥1 mythique), 3 éligibles | D43: P(≥1 mythique), 4 éligibles | E43: Mythiques attendues (4) | F43: Montées de niveau avant la 1re (4), en moyenne
A44: 0 | B44: =MIN(100,$B$39+$B$40*A44)/100 -> 0.005 | C44: =1-(1-B44)^$B$41 -> 0.014925125 | D44: =1-(1-B44)^($B$41+$B$42) -> 0.019850499 | E44: =($B$41+$B$42)*B44 -> 0.02 | F44: =1/D44 -> 50.376566
...

Sheet Reliques
A1: Butin de reliques
A2: RewardController.handleVictory, EventController.selectChoice('gain_relic'), RelicExchangeScreen
A4: A. Le pool : 28 reliques par rareté (assets/data/relics/*.json)
A5: Rareté | B5: Nombre | C5: Reliques
A6: Commune | B6: 5 | C6: Bandage de voyage, Talisman de Fer, Bottes en cuir, Pièce de chance, Pierre à aiguiser
A7: Peu commune | B7: 6 | C7: Bouclier Ancestral, Lame Maudite, Porte-bonheur, Plume de scribe, Rune de Protection, Croc Vampirique
A8: Rare | B8: 10 | C8: Registre des primes, Lentille de Focalisation, Sacoche du glaneur, Encensoir, Croc Kunaï, Amulette du Mage, Cristal de Mana, Anneau de Régénération, Shuriken, Essence Spirituelle
A9: Épique | B9: 3 | C9: Pierre d'Énergie, Trèfle Enchanté, Plume de Phénix
A10: Légendaire | B10: 4 | C10: Couronne des Rois, Dé de Fortune, Meule, Besace de l'Érudit
A11: Total | B11: =SUM(B6:B10) -> 28
A12: Une relique déjà possédée n'est pas exclue du tirage (filtre par rareté seulement) : les doublons sont possibles, et leurs effets s'additionnent.
A14: B. Élite et événement (gain_relic) : poids en points selon la Chance
A15: Source : reward_controller.dart l.165-168 et event_controller.dart l.174-177 : légendaire 1 + 0,5 L ; épique 5 + L ; rare 14 + 2 L ; peu commune 20 + 3 L ; commune = le reste (cascade : roll < cumul)
A16: Rareté | B16: Base (pts) | C16: Par point de Chance
A17: Légendaire | B17: 1 | C17: 0.5
A18: Épique | B18: 5 | C18: 1
A19: Rare | B19: 14 | C19: 2
A20: Peu commune | B20: 20 | C20: 3
A21: Chance | B21: Légendaire | C21: Épique | D21: Rare | E21: Peu commune | F21: Commune | G21: P(une légendaire précise) | H21: P(une épique précise) | I21: P(une rare précise) | J21: P(une peu commune précise) | K21: P(une commune précise)
A22: 0 | B22: =MIN(100,$B$17+$C$17*A22)/100 -> 0.01 | C22: =(MIN(100,$B$17+$C$17*A22+$B$18+$C$18*A22)-MIN(100,$B$17+$C$17*A22))/100 -> 0.05 | D22: =(MIN(100,$B$17+$C$17*A22+$B$18+$C$18*A22+$B$19+$C$19*A22)-MIN(100,$B$17+$C$17*A22+$B$18+$C$18*A22))/100 -> 0.14 | E22: =(MIN(100,$B$17+$C$17*A22+$B$18+$C$18*A22+$B$19+$C$19*A22+$B$20+$C$20*A22)-MIN(100,$B$17+$C$17*A22+$B$18+$C$18*A22+$B$19+$C$19*A22))/100 -> 0.2 | F22: =1-MIN(100,$B$17+$C$17*A22+$B$18+$C$18*A22+$B$19+$C$19*A22+$B$20+$C$20*A22)/100 -> 0.6 | G22: =B22/$B$10 -> 0.0025 | H22: =C22/$B$9 -> 0.016666667 | I22: =D22/$B$8 -> 0.014 | J22: =E22/$B$7 -> 0.033333333 | K22: =F22/$B$6 -> 0.12
A23: 1 | B23: =MIN(100,$B$17+$C$17*A23)/100 -> 0.015 | C23: =(MIN(100,$B$17+$C$17*A23+$B$18+$C$18*A23)-MIN(100,$B$17+$C$17*A23))/100 -> 0.06 | D23: =(MIN(100,$B$17+$C$17*A23+$B$18+$C$18*A23+$B$19+$C$19*A23)-MIN(100,$B$17+$C$17*A23+$B$18+$C$18*A23))/100 -> 0.16 | E23: =(MIN(100,$B$17+$C$17*A23+$B$18+$C$18*A23+$B$19+$C$19*A23+$B$20+$C$20*A23)-MIN(100,$B$17+$C$17*A23+$B$18+$C$18*A23+$B$19+$C$19*A23))/100 -> 0.23 | F23: =1-MIN(100,$B$17+$C$17*A23+$B$18+$C$18*A23+$B$19+$C$19*A23+$B$20+$C$20*A23)/100 -> 0.535 | G23: =B23/$B$10 -> 0.00375 | H23: =C23/$B$9 -> 0.02 | I23: =D23/$B$8 -> 0.016 | J23: =E23/$B$7 -> 0.038333333 | K23: =F23/$B$6 -> 0.107
A24: 2 | B24: =MIN(100,$B$17+$C$17*A24)/100 -> 0.02 | C24: =(MIN(100,$B$17+$C$17*A24+$B$18+$C$18*A24)-MIN(100,$B$17+$C$17*A24))/100 -> 0.07 | D24: =(MIN(100,$B$17+$C$17*A24+$B$18+$C$18*A24+$B$19+$C$19*A24)-MIN(100,$B$17+$C$17*A24+$B$18+$C$18*A24))/100 -> 0.18 | E24: =(MIN(100,$B$17+$C$17*A24+$B$18+$C$18*A24+$B$19+$C$19*A24+$B$20+$C$20*A24)-MIN(100,$B$17+$C$17*A24+$B$18+$C$18*A24+$B$19+$C$19*A24))/100 -> 0.26 | F24: =1-MIN(100,$B$17+$C$17*A24+$B$18+$C$18*A24+$B$19+$C$19*A24+$B$20+$C$20*A24)/100 -> 0.47 | G24: =B24/$B$10 -> 0.005 | H24: =C24/$B$9 -> 0.023333333 | I24: =D24/$B$8 -> 0.018 | J24: =E24/$B$7 -> 0.043333333 | K24: =F24/$B$6 -> 0.094
A25: 3 | B25: =MIN(100,$B$17+$C$17*A25)/100 -> 0.025 | C25: =(MIN(100,$B$17+$C$17*A25+$B$18+$C$18*A25)-MIN(100,$B$17+$C$17*A25))/100 -> 0.08 | D25: =(MIN(100,$B$17+$C$17*A25+$B$18+$C$18*A25+$B$19+$C$19*A25)-MIN(100,$B$17+$C$17*A25+$B$18+$C$18*A25))/100 -> 0.2 | E25: =(MIN(100,$B$17+$C$17*A25+$B$18+$C$18*A25+$B$19+$C$19*A25+$B$20+$C$20*A25)-MIN(100,$B$17+$C$17*A25+$B$18+$C$18*A25+$B$19+$C$19*A25))/100 -> 0.29 | F25: =1-MIN(100,$B$17+$C$17*A25+$B$18+$C$18*A25+$B$19+$C$19*A25+$B$20+$C$20*A25)/100 -> 0.405 | G25: =B25/$B$10 -> 0.00625 | H25: =C25/$B$9 -> 0.026666667 | I25: =D25/$B$8 -> 0.02 | J25: =E25/$B$7 -> 0.048333333 | K25: =F25/$B$6 -> 0.081
A26: 4 | B26: =MIN(100,$B$17+$C$17*A26)/100 -> 0.03 | C26: =(MIN(100,$B$17+$C$17*A26+$B$18+$C$18*A26)-MIN(100,$B$17+$C$17*A26))/100 -> 0.09 | D26: =(MIN(100,$B$17+$C$17*A26+$B$18+$C$18*A26+$B$19+$C$19*A26)-MIN(100,$B$17+$C$17*A26+$B$18+$C$18*A26))/100 -> 0.22 | E26: =(MIN(100,$B$17+$C$17*A26+$B$18+$C$18*A26+$B$19+$C$19*A26+$B$20+$C$20*A26)-MIN(100,$B$17+$C$17*A26+$B$18+$C$18*A26+$B$19+$C$19*A26))/100 -> 0.32 | F26: =1-MIN(100,$B$17+$C$17*A26+$B$18+$C$18*A26+$B$19+$C$19*A26+$B$20+$C$20*A26)/100 -> 0.34 | G26: =B26/$B$10 -> 0.0075 | H26: =C26/$B$9 -> 0.03 | I26: =D26/$B$8 -> 0.022 | J26: =E26/$B$7 -> 0.053333333 | K26: =F26/$B$6 -> 0.068
A27: 5 | B27: =MIN(100,$B$17+$C$17*A27)/100 -> 0.035 | C27: =(MIN(100,$B$17+$C$17*A27+$B$18+$C$18*A27)-MIN(100,$B$17+$C$17*A27))/100 -> 0.1 | D27: =(MIN(100,$B$17+$C$17*A27+$B$18+$C$18*A27+$B$19+$C$19*A27)-MIN(100,$B$17+$C$17*A27+$B$18+$C$18*A27))/100 -> 0.24 | E27: =(MIN(100,$B$17+$C$17*A27+$B$18+$C$18*A27+$B$19+$C$19*A27+$B$20+$C$20*A27)-MIN(100,$B$17+$C$17*A27+$B$18+$C$18*A27+$B$19+$C$19*A27))/100 -> 0.35 | F27: =1-MIN(100,$B$17+$C$17*A27+$B$18+$C$18*A27+$B$19+$C$19*A27+$B$20+$C$20*A27)/100 -> 0.275 | G27: =B27/$B$10 -> 0.00875 | H27: =C27/$B$9 -> 0.033333333 | I27: =D27/$B$8 -> 0.024 | J27: =E27/$B$7 -> 0.058333333 | K27: =F27/$B$6 -> 0.055
A28: 6 | B28: =MIN(100,$B$17+$C$17*A28)/100 -> 0.04 | C28: =(MIN(100,$B$17+$C$17*A28+$B$18+$C$18*A28)-MIN(100,$B$17+$C$17*A28))/100 -> 0.11 | D28: =(MIN(100,$B$17+$C$17*A28+$B$18+$C$18*A28+$B$19+$C$19*A28)-MIN(100,$B$17+$C$17*A28+$B$18+$C$18*A28))/100 -> 0.26 | E28: =(MIN(100,$B$17+$C$17*A28+$B$18+$C$18*A28+$B$19+$C$19*A28+$B$20+$C$20*A28)-MIN(100,$B$17+$C$17*A28+$B$18+$C$18*A28+$B$19+$C$19*A28))/100 -> 0.38 | F28: =1-MIN(100,$B$17+$C$17*A28+$B$18+$C$18*A28+$B$19+$C$19*A28+$B$20+$C$20*A28)/100 -> 0.21 | G28: =B28/$B$10 -> 0.01 | H28: =C28/$B$9 -> 0.036666667 | I28: =D28/$B$8 -> 0.026 | J28: =E28/$B$7 -> 0.063333333 | K28: =F28/$B$6 -> 0.042
A29: 7 | B29: =MIN(100,$B$17+$C$17*A29)/100 -> 0.045 | C29: =(MIN(100,$B$17+$C$17*A29+$B$18+$C$18*A29)-MIN(100,$B$17+$C$17*A29))/100 -> 0.12 | D29: =(MIN(100,$B$17+$C$17*A29+$B$18+$C$18*A29+$B$19+$C$19*A29)-MIN(100,$B$17+$C$17*A29+$B$18+$C$18*A29))/100 -> 0.28 | E29: =(MIN(100,$B$17+$C$17*A29+$B$18+$C$18*A29+$B$19+$C$19*A29+$B$20+$C$20*A29)-MIN(100,$B$17+$C$17*A29+$B$18+$C$18*A29+$B$19+$C$19*A29))/100 -> 0.41 | F29: =1-MIN(100,$B$17+$C$17*A29+$B$18+$C$18*A29+$B$19+$C$19*A29+$B$20+$C$20*A29)/100 -> 0.145 | G29: =B29/$B$10 -> 0.01125 | H29: =C29/$B$9 -> 0.04 | I29: =D29/$B$8 -> 0.028 | J29: =E29/$B$7 -> 0.068333333 | K29: =F29/$B$6 -> 0.029
A30: 8 | B30: =MIN(100,$B$17+$C$17*A30)/100 -> 0.05 | C30: =(MIN(100,$B$17+$C$17*A30+$B$18+$C$18*A30)-MIN(100,$B$17+$C$17*A30))/100 -> 0.13 | D30: =(MIN(100,$B$17+$C$17*A30+$B$18+$C$18*A30+$B$19+$C$19*A30)-MIN(100,$B$17+$C$17*A30+$B$18+$C$18*A30))/100 -> 0.3 | E30: =(MIN(100,$B$17+$C$17*A30+$B$18+$C$18*A30+$B$19+$C$19*A30+$B$20+$C$20*A30)-MIN(100,$B$17+$C$17*A30+$B$18+$C$18*A30+$B$19+$C$19*A30))/100 -> 0.44 | F30: =1-MIN(100,$B$17+$C$17*A30+$B$18+$C$18*A30+$B$19+$C$19*A30+$B$20+$C$20*A30)/100 -> 0.08 | G30: =B30/$B$10 -> 0.0125 | H30: =C30/$B$9 -> 0.043333333 | I30: =D30/$B$8 -> 0.03 | J30: =E30/$B$7 -> 0.073333333 | K30: =F30/$B$6 -> 0.016
A31: 9 | B31: =MIN(100,$B$17+$C$17*A31)/100 -> 0.055 | C31: =(MIN(100,$B$17+$C$17*A31+$B$18+$C$18*A31)-MIN(100,$B$17+$C$17*A31))/100 -> 0.14 | D31: =(MIN(100,$B$17+$C$17*A31+$B$18+$C$18*A31+$B$19+$C$19*A31)-MIN(100,$B$17+$C$17*A31+$B$18+$C$18*A31))/100 -> 0.32 | E31: =(MIN(100,$B$17+$C$17*A31+$B$18+$C$18*A31+$B$19+$C$19*A31+$B$20+$C$20*A31)-MIN(100,$B$17+$C$17*A31+$B$18+$C$18*A31+$B$19+$C$19*A31))/100 -> 0.47 | F31: =1-MIN(100,$B$17+$C$17*A31+$B$18+$C$18*A31+$B$19+$C$19*A31+$B$20+$C$20*A31)/100 -> 0.015 | G31: =B31/$B$10 -> 0.01375 | H31: =C31/$B$9 -> 0.046666667 | I31: =D31/$B$8 -> 0.032 | J31: =E31/$B$7 -> 0.078333333 | K31: =F31/$B$6 -> 0.003
A32: 10 | B32: =MIN(100,$B$17+$C$17*A32)/100 -> 0.06 | C32: =(MIN(100,$B$17+$C$17*A32+$B$18+$C$18*A32)-MIN(100,$B$17+$C$17*A32))/100 -> 0.15 | D32: =(MIN(100,$B$17+$C$17*A32+$B$18+$C$18*A32+$B$19+$C$19*A32)-MIN(100,$B$17+$C$17*A32+$B$18+$C$18*A32))/100 -> 0.34 | E32: =(MIN(100,$B$17+$C$17*A32+$B$18+$C$18*A32+$B$19+$C$19*A32+$B$20+$C$20*A32)-MIN(100,$B$17+$C$17*A32+$B$18+$C$18*A32+$B$19+$C$19*A32))/100 -> 0.45 | F32: =1-MIN(100,$B$17+$C$17*A32+$B$18+$C$18*A32+$B$19+$C$19*A32+$B$20+$C$20*A32)/100 -> 0 | G32: =B32/$B$10 -> 0.015 | H32: =C32/$B$9 -> 0.05 | I32: =D32/$B$8 -> 0.034 | J32: =E32/$B$7 -> 0.075 | K32: =F32/$B$6 -> 0
A33: 11 | B33: =MIN(100,$B$17+$C$17*A33)/100 -> 0.065 | C33: =(MIN(100,$B$17+$C$17*A33+$B$18+$C$18*A33)-MIN(100,$B$17+$C$17*A33))/100 -> 0.16 | D33: =(MIN(100,$B$17+$C$17*A33+$B$18+$C$18*A33+$B$19+$C$19*A33)-MIN(100,$B$17+$C$17*A33+$B$18+$C$18*A33))/100 -> 0.36 | E33: =(MIN(100,$B$17+$C$17*A33+$B$18+$C$18*A33+$B$19+$C$19*A33+$B$20+$C$20*A33)-MIN(100,$B$17+$C$17*A33+$B$18+$C$18*A33+$B$19+$C$19*A33))/100 -> 0.415 | F33: =1-MIN(100,$B$17+$C$17*A33+$B$18+$C$18*A33+$B$19+$C$19*A33+$B$20+$C$20*A33)/100 -> 0 | G33: =B33/$B$10 -> 0.01625 | H33: =C33/$B$9 -> 0.053333333 | I33: =D33/$B$8 -> 0.036 | J33: =E33/$B$7 -> 0.069166667 | K33: =F33/$B$6 -> 0
A34: 12 | B34: =MIN(100,$B$17+$C$17*A34)/100 -> 0.07 | C34: =(MIN(100,$B$17+$C$17*A34+$B$18+$C$18*A34)-MIN(100,$B$17+$C$17*A34))/100 -> 0.17 | D34: =(MIN(100,$B$17+$C$17*A34+$B$18+$C$18*A34+$B$19+$C$19*A34)-MIN(100,$B$17+$C$17*A34+$B$18+$C$18*A34))/100 -> 0.38 | E34: =(MIN(100,$B$17+$C$17*A34+$B$18+$C$18*A34+$B$19+$C$19*A34+$B$20+$C$20*A34)-MIN(100,$B$17+$C$17*A34+$B$18+$C$18*A34+$B$19+$C$19*A34))/100 -> 0.38 | F34: =1-MIN(100,$B$17+$C$17*A34+$B$18+$C$18*A34+$B$19+$C$19*A34+$B$20+$C$20*A34)/100 -> 0 | G34: =B34/$B$10 -> 0.0175 | H34: =C34/$B$9 -> 0.056666667 | I34: =D34/$B$8 -> 0.038 | J34: =E34/$B$7 -> 0.063333333 | K34: =F34/$B$6 -> 0
A35: Chance 0 : 1 / 5 / 14 / 20 / 60 %. Tiré pour : tout nœud Élite gagné, et les choix d'événement portant gain_relic (Marchand fugitif ×2, Feu de camp abandonné ×1).
A37: C. Boss « relique améliorée » (x = 2) : poids selon l'acte et la Chance
A38: Source : reward_controller.dart l.142-163 : légendaire 10 + 0,5 L ; part commune 40 − 10 × (acte − 1) jusqu'à 0 ; le reste de 90 réparti 20/35/30 (peu commune/rare/épique) sur 85 ; dès que la commune est à 0, la peu commune décroît de 10 par acte depuis 21,18 et le reste se répartit 35/30 sur 65 ; bonus de Chance : +3 / +2 / +1 pts
A39: La fiche de règles (_rules/02-1) écrit « exclut totalement les communes » et « 15/30/35/20 % » : le code tire 40 % de communes à l'acte 1 et 10 % de légendaires. Ce classeur suit le code.
A40: Chance du scénario | B40: 0
A41: Acte | B41: Part commune (pts) | C41: Base peu commune si commune = 0 | D41: Poids légendaire | E41: Poids épique | F41: Poids rare | G41: Poids peu commune | H41: P(Légendaire) | I41: P(Épique) | J41: P(Rare) | K41: P(Peu commune) | L41: P(Commune) | M41: Somme
A42: 1 | B42: =MAX(0,40-(A42-1)*10) -> 40 | C42: =IF(B42>0,0,MAX(0,20/85*90-(A42-5)*10)) -> 0 | D42: =10+0.5*$B$40 -> 10 | E42: =IF(B42>0,30/85*(90-B42)+$B$40,IF(C42>0,30/65*(90-C42)+$B$40,30/65*90+$B$40)) -> 17.647059 | F42: =IF(B42>0,35/85*(90-B42)+2*$B$40,IF(C42>0,35/65*(90-C42)+2*$B$40,35/65*90+2*$B$40)) -> 20.588235 | G42: =IF(B42>0,20/85*(90-B42)+3*$B$40,IF(C42>0,C42+3*$B$40,0)) -> 11.764706 | H42: =MIN(D42,100)/100 -> 0.1 | I42: =(MIN(D42+E42,100)-MIN(D42,100))/100 -> 0.17647059 | J42: =(MIN(D42+E42+F42,100)-MIN(D42+E42,100))/100 -> 0.20588235 | K42: =(MIN(D42+E42+F42+G42,100)-MIN(D42+E42+F42,100))/100 -> 0.11764706 | L42: =1-MIN(D42+E42+F42+G42,100)/100 -> 0.4 | M42: =SUM(H42:L42) -> 1
A43: 2 | B43: =MAX(0,40-(A43-1)*10) -> 30 | C43: =IF(B43>0,0,MAX(0,20/85*90-(A43-5)*10)) -> 0 | D43: =10+0.5*$B$40 -> 10 | E43: =IF(B43>0,30/85*(90-B43)+$B$40,IF(C43>0,30/65*(90-C43)+$B$40,30/65*90+$B$40)) -> 21.176471 | F43: =IF(B43>0,35/85*(90-B43)+2*$B$40,IF(C43>0,35/65*(90-C43)+2*$B$40,35/65*90+2*$B$40)) -> 24.705882 | G43: =IF(B43>0,20/85*(90-B43)+3*$B$40,IF(C43>0,C43+3*$B$40,0)) -> 14.117647 | H43: =MIN(D43,100)/100 -> 0.1 | I43: =(MIN(D43+E43,100)-MIN(D43,100))/100 -> 0.21176471 | J43: =(MIN(D43+E43+F43,100)-MIN(D43+E43,100))/100 -> 0.24705882 | K43: =(MIN(D43+E43+F43+G43,100)-MIN(D43+E43+F43,100))/100 -> 0.14117647 | L43: =1-MIN(D43+E43+F43+G43,100)/100 -> 0.3 | M43: =SUM(H43:L43) -> 1
...

Sheet Trouvaille
A1: La trouvaille : des cartes après chaque combat
A2: CardDrops.roll (lib/game/systems/card_drops.dart) + GameConstants.cardDrops + RewardController.handleVictory
A4: A. Règles par type de nœud
A5: Source : GameConstants.cardDrops : combat (1 garantie) ; élite (1 garantie, puis un jet à 25 % pour une seconde) ; boss et autres : aucune
A6: Combat : cartes garanties | B6: 1
A7: Élite : cartes garanties | B7: 1
A8: Élite : chance d'une seconde (pts) | B8: 25
A9: Registre des primes : +pts sur ce jet, par exemplaire | B9: 25 | C9: relic bounty_ledger (rare)
A10: Sacoche du glaneur : +cartes garanties (combat), par exemplaire | B10: 1 | C10: relic gleaners_pouch (rare)
A11: Exemplaires de la relique | B11: Combat : cartes attendues | C11: Élite : P(2e carte) | D11: Élite : cartes attendues | E11: Boss
A12: 0 | B12: =$B$6+$B$10*A12 -> 1 | C12: =MIN(1,($B$8+$B$9*A12)/100) -> 0.25 | D12: =$B$7+C12 -> 1.25 | E12: 0
A13: 1 | B13: =$B$6+$B$10*A13 -> 2 | C13: =MIN(1,($B$8+$B$9*A13)/100) -> 0.5 | D13: =$B$7+C13 -> 1.5 | E13: 0
A14: 2 | B14: =$B$6+$B$10*A14 -> 3 | C14: =MIN(1,($B$8+$B$9*A14)/100) -> 0.75 | D14: =$B$7+C14 -> 1.75 | E14: 0
A15: 3 | B15: =$B$6+$B$10*A15 -> 4 | C15: =MIN(1,($B$8+$B$9*A15)/100) -> 1 | D15: =$B$7+C15 -> 2 | E15: 0
A16: 4 | B16: =$B$6+$B$10*A16 -> 5 | C16: =MIN(1,($B$8+$B$9*A16)/100) -> 1 | D16: =$B$7+C16 -> 2 | E16: 0
A17: La Sacoche n'agit que sur le combat normal, le Registre que sur l'élite ; jamais l'une sur le nœud de l'autre, jamais sur un boss (D31, D57).
A19: B. Quelle carte ? Tirage uniforme AVEC remise parmi les cartes offrables (CardData.isOfferableTo)
A20: Cartes offrables (neutres, non uniques) | B20: 17 | C20: Éveil, Concentration, Défense, Forme Démoniaque, Boule de Feu, Focalisation, Potion de Soin, Frappe Lourde, Trait de Glace, Mur de Fer, Métallisation, Coup Empoisonné, Attaque Rapide, Frappe, Balayage, Coup de Tonnerre, Cri de Guerre
A21: P(une carte précise, par carte trouvée) | B21: =1/$B$20 -> 0.058823529
A22: Les cartes de classe (rareté unique) ne sont jamais trouvées ; une trouvaille est toujours commune, sans rune.
A24: C. Copies cumulées d'une carte précise après n cartes trouvées (loi binomiale, p = 1/pool)
A25: n cartes trouvées | B25: Copies attendues | C25: P(≥ 1 copie) | D25: P(≥ 2 copies) | E25: P(≥ 3 copies) = fusion possible | F25: Cartes du pool avec ≥ 3 copies (attendu)
A26: 1 | B26: =A26/$B$20 -> 0.058823529 | C26: =1-(1-1/$B$20)^A26 -> 0.058823529 | D26: =IF(A26<2,0,1-_xlfn.BINOM.DIST(1,A26,1/$B$20,TRUE)) -> 0 | E26: =IF(A26<3,0,1-_xlfn.BINOM.DIST(2,A26,1/$B$20,TRUE)) -> 0 | F26: =$B$20*E26 -> 0
A27: 2 | B27: =A27/$B$20 -> 0.11764706 | C27: =1-(1-1/$B$20)^A27 -> 0.11418685 | D27: =IF(A27<2,0,1-_xlfn.BINOM.DIST(1,A27,1/$B$20,TRUE)) -> 0.0034602076 | E27: =IF(A27<3,0,1-_xlfn.BINOM.DIST(2,A27,1/$B$20,TRUE)) -> 0 | F27: =$B$20*E27 -> 0
A28: 3 | B28: =A28/$B$20 -> 0.17647059 | C28: =1-(1-1/$B$20)^A28 -> 0.16629351 | D28: =IF(A28<2,0,1-_xlfn.BINOM.DIST(1,A28,1/$B$20,TRUE)) -> 0.0099735396 | E28: =IF(A28<3,0,1-_xlfn.BINOM.DIST(2,A28,1/$B$20,TRUE)) -> 0.00020354162 | F28: =$B$20*E28 -> 0.0034602076
A29: 4 | B29: =A29/$B$20 -> 0.23529412 | C29: =1-(1-1/$B$20)^A29 -> 0.21533507 | D29: =IF(A29<2,0,1-_xlfn.BINOM.DIST(1,A29,1/$B$20,TRUE)) -> 0.019168832 | E29: =IF(A29<3,0,1-_xlfn.BINOM.DIST(2,A29,1/$B$20,TRUE)) -> 0.00077824739 | F29: =$B$20*E29 -> 0.013230206
A30: 5 | B30: =A30/$B$20 -> 0.29411765 | C30: =1-(1-1/$B$20)^A30 -> 0.26149183 | D30: =IF(A30<2,0,1-_xlfn.BINOM.DIST(1,A30,1/$B$20,TRUE)) -> 0.030708022 | E30: =IF(A30<3,0,1-_xlfn.BINOM.DIST(2,A30,1/$B$20,TRUE)) -> 0.0018600465 | F30: =$B$20*E30 -> 0.03162079
A31: 6 | B31: =A31/$B$20 -> 0.35294118 | C31: =1-(1-1/$B$20)^A31 -> 0.30493348 | D31: =IF(A31<2,0,1-_xlfn.BINOM.DIST(1,A31,1/$B$20,TRUE)) -> 0.04428354 | E31: =IF(A31<3,0,1-_xlfn.BINOM.DIST(2,A31,1/$B$20,TRUE)) -> 0.0035569862 | F31: =$B$20*E31 -> 0.060468766
A32: 7 | B32: =A32/$B$20 -> 0.41176471 | C32: =1-(1-1/$B$20)^A32 -> 0.34581975 | D32: =IF(A32<2,0,1-_xlfn.BINOM.DIST(1,A32,1/$B$20,TRUE)) -> 0.05961589 | E32: =IF(A32<3,0,1-_xlfn.BINOM.DIST(2,A32,1/$B$20,TRUE)) -> 0.0059526658 | F32: =$B$20*E32 -> 0.10119532
A33: 8 | B33: =A33/$B$20 -> 0.47058824 | C33: =1-(1-1/$B$20)^A33 -> 0.38430094 | D33: =IF(A33<2,0,1-_xlfn.BINOM.DIST(1,A33,1/$B$20,TRUE)) -> 0.076451411 | E33: =IF(A33<3,0,1-_xlfn.BINOM.DIST(2,A33,1/$B$20,TRUE)) -> 0.0091093261 | F33: =$B$20*E33 -> 0.15485854
A34: 9 | B34: =A34/$B$20 -> 0.52941176 | C34: =1-(1-1/$B$20)^A34 -> 0.42051853 | D34: =IF(A34<2,0,1-_xlfn.BINOM.DIST(1,A34,1/$B$20,TRUE)) -> 0.094560207 | E34: =IF(A34<3,0,1-_xlfn.BINOM.DIST(2,A34,1/$B$20,TRUE)) -> 0.013070625 | F34: =$B$20*E34 -> 0.22220063
A35: 10 | B35: =A35/$B$20 -> 0.58823529 | C35: =1-(1-1/$B$20)^A35 -> 0.45460568 | D35: =IF(A35<2,0,1-_xlfn.BINOM.DIST(1,A35,1/$B$20,TRUE)) -> 0.11373423 | E35: =IF(A35<3,0,1-_xlfn.BINOM.DIST(2,A35,1/$B$20,TRUE)) -> 0.01786413 | F35: =$B$20*E35 -> 0.30369021
A36: 12 | B36: =A36/$B$20 -> 0.70588235 | C36: =1-(1-1/$B$20)^A36 -> 0.51688254 | D36: =IF(A36<2,0,1-_xlfn.BINOM.DIST(1,A36,1/$B$20,TRUE)) -> 0.15454444 | E36: =IF(A36<3,0,1-_xlfn.BINOM.DIST(2,A36,1/$B$20,TRUE)) -> 0.02999072 | F36: =$B$20*E36 -> 0.50984224
A37: 15 | B37: =A37/$B$20 -> 0.88235294 | C37: =1-(1-1/$B$20)^A37 -> 0.59722183 | D37: =IF(A37<2,0,1-_xlfn.BINOM.DIST(1,A37,1/$B$20,TRUE)) -> 0.2196173 | E37: =IF(A37<3,0,1-_xlfn.BINOM.DIST(2,A37,1/$B$20,TRUE)) -> 0.054415323 | F37: =$B$20*E37 -> 0.92506049
... A42: 50 | B42: =A42/$B$20 -> 2.9411765 | C42: =1-(1-1/$B$20)^A42 -> 0.95174381 | D42: =IF(A42<2,0,1-_xlfn.BINOM.DIST(1,A42,1/$B$20,TRUE)) -> 0.8009432 | E42: =IF(A42<3,0,1-_xlfn.BINOM.DIST(2,A42,1/$B$20,TRUE)) -> 0.57002977 | F42: =$B$20*E42 -> 9.6905061
A44: D. Cartes trouvées par acte (scénario de parcours)
A45: Combats normaux sur le chemin d'un acte | B45: 6
A46: Élites sur le chemin d'un acte | B46: 1
A47: Sacoches portées | B47: 0
A48: Registres portés | B48: 0
...

Sheet Boutique
A1: Boutique : l'étal et ses tirages
A2: ShopController (lib/game/controllers/shop_controller.dart) + ShopScreen pour les prix
A4: A. Rareté finale d'une carte en vente, selon l'acte
A5: Source : ShopController._rollRarity : acte 1 → +1 rang si roll < 10 ; acte 2 → +1 si roll < 25 ; acte ≥ 3 → +2 si roll < 10, +1 si roll < 50. Toutes les cartes offrables sont communes : +0 = commune, +1 = peu commune, +2 = rare.
A6: Acte 1 : seuil +1 (pts) | B6: 10
A7: Acte 2 : seuil +1 (pts) | B7: 25
A8: Acte ≥ 3 : seuil +2 (pts) | B8: 10
A9: Acte ≥ 3 : seuil +1 (pts, cumulé) | B9: 50
A10: Acte | B10: P(Commune) | C10: P(Peu commune) | D10: P(Rare)
A11: 1 | B11: =1-$B$6/100 -> 0.9 | C11: =$B$6/100 -> 0.1 | D11: 0
A12: 2 | B12: =1-$B$7/100 -> 0.75 | C12: =$B$7/100 -> 0.25 | D12: 0
A13: 3 et plus | B13: =1-$B$9/100 -> 0.5 | C13: =($B$9-$B$8)/100 -> 0.4 | D13: =$B$8/100 -> 0.1
A15: B. Runes pré-forgées : nombre tiré, puis borné par le rang de fusion de la rareté finale
A16: Source : _generateShopCardInstance : acte 1 → 0 ; acte 2 → 1 si roll < 15 ; acte ≥ 3 → 2 si roll < 10, 1 si roll < 40 ; maxUpgrades = fusionRank (commune 0, peu commune 1, rare 2) ; une rune sans candidat éligible est perdue
A17: Acte 2 : seuil 1 rune (pts) | B17: 15
A18: Acte ≥ 3 : seuil 2 runes (pts) | B18: 10
A19: Acte ≥ 3 : seuil 1 rune (pts, cumulé) | B19: 40
A20: Acte ≥ 3 — rareté finale | B20: P(rareté) | C20: Plafond de runes | D20: P(0 rune | rareté) | E20: P(1 rune | rareté) | F20: P(2 runes | rareté) | G20: P(rareté ∧ 0) | H20: P(rareté ∧ 1) | I20: P(rareté ∧ 2)
A21: Commune | B21: =$B$13 -> 0.5 | C21: 0 | D21: 1 | E21: 0 | F21: 0 | G21: =B21*D21 -> 0.5 | H21: =B21*E21 -> 0 | I21: =B21*F21 -> 0
A22: Peu commune | B22: =$C$13 -> 0.4 | C22: 1 | D22: =1-$B$19/100 -> 0.6 | E22: =$B$19/100 -> 0.4 | F22: 0 | G22: =B22*D22 -> 0.24 | H22: =B22*E22 -> 0.16 | I22: =B22*F22 -> 0
A23: Rare | B23: =$D$13 -> 0.1 | C23: 2 | D23: =1-$B$19/100 -> 0.6 | E23: =($B$19-$B$18)/100 -> 0.3 | F23: =$B$18/100 -> 0.1 | G23: =B23*D23 -> 0.06 | H23: =B23*E23 -> 0.03 | I23: =B23*F23 -> 0.01
A24: Total (acte ≥ 3) | B24: =SUM(B21:B23) -> 1 | G24: =SUM(G21:G23) -> 0.8 | H24: =SUM(H21:H23) -> 0.19 | I24: =SUM(I21:I23) -> 0.01
A25: Runes attendues par carte (acte ≥ 3) | B25: =H21+H22+H23+2*(I21+I22+I23) -> 0.21
A27: Acte 2 — rareté finale | B27: P(rareté) | C27: Plafond de runes | D27: P(0 rune | rareté) | E27: P(1 rune | rareté) | G27: P(rareté ∧ 0) | H27: P(rareté ∧ 1)
A28: Commune | B28: =$B$12 -> 0.75 | C28: 0 | D28: 1 | E28: 0 | G28: =B28*D28 -> 0.75 | H28: =B28*E28 -> 0
A29: Peu commune | B29: =$C$12 -> 0.25 | C29: 1 | D29: =1-$B$17/100 -> 0.85 | E29: =$B$17/100 -> 0.15 | G29: =B29*D29 -> 0.2125 | H29: =B29*E29 -> 0.0375
A30: Acte 1 : jamais de rune (aucun jet). La rune elle-même est tirée comme à la fusion : onglet Runes.
A32: C. Niveau d'une rune pré-forgée
A33: Source : _rollRandomUpgrade : roll < 80 → niveau 1 ; < 95 → 2 ; sinon 3 ; puis borné par maxLevel + bonus Transcendance
A34: Niveau tiré | B34: Probabilité | C34: Runes à plafond 1 (toujours niveau 1)
A35: 1 | B35: 0.8 | C35: Allégé, Économe, Persistant, Congelant, Véloce
A36: 2 | B36: 0.15
A37: 3 | B37: 0.05
A38: Niveau attendu (rune sans plafond) | B38: =SUMPRODUCT(A35:A37,B35:B37) -> 1.25
A40: D. L'étal : quelles cartes ?
A41: Source : initializeShop : cartes offrables mélangées, les 3 + bonus premières (sans remise) ; copie du deck : uniforme parmi DeckState.copyableCards
A42: Cartes offrables | B42: 17
A43: Cartes en vente (3 + expansions achetées) | B43: 3
A44: P(une carte précise est à l'étal) | B44: =1-COMBIN($B$42-1,$B$43)/COMBIN($B$42,$B$43) -> 0.17647059 | C44: soit n / 17 (tirage sans remise)
A45: Cartes copiables du deck (deck − cartes de classe) | B45: 10
...

Sheet Runes
A1: Tirage des runes (fusion 3→1, boutique pré-forgée, Puits)
A2: ForgeRuneRules.isEligible + drawRunes (lib/game/services/forge_rune_rules.dart) — pondéré par weight, sans remise
A4: A. Catalogue des runes (assets/data/forge_upgrades/*.json)
A5: Rune | B5: id | C5: Poids | D5: Rang min | E5: Plafond | F5: Binaire | J5: Éligibilité
A6: Brûlant | B6: burning | C6: 80 | D6: 1 | E6: aucun | J6: types attack
A7: Allégé | B7: cheap | C7: 50 | D7: 1 | E7: 1 | F7: oui | J7: coût ≥ 1 ; exclut eco
A8: Économe | B8: eco | C8: 40 | D8: 2 | E8: 1 | J8: types attack/skill/power ; coût ≥ 1
A9: Persistant | B9: enduring | C9: 30 | D9: 1 | E9: 1 | F9: oui | J9: types attack/skill/power ; sans effet gain_mana/draw ; carte à Épuisement ; exclut eco/quick
A10: Congelant | B10: freezing | C10: 80 | D10: 1 | E10: 1 | J10: types attack
A11: Endurci | B11: hardened | C11: 100 | D11: 1 | E11: aucun | J11: effet armor
A12: Précis | B12: precise | C12: 50 | D12: 1 | E12: 10 | J12: effet damage
A13: Véloce | B13: quick | C13: 60 | D13: 2 | E13: 1 | J13: types attack/skill/power
A14: Tranchant | B14: sharp | C14: 100 | D14: 1 | E14: aucun | J14: effet damage
A15: Surchargé | B15: shocking | C15: 80 | D15: 1 | E15: aucun | J15: types attack
A16: Spectral | B16: spectral | C16: 50 | D16: 1 | E16: aucun | J16: effet damage
A17: Une rune portée ne se repropose jamais ; deux runes qui s'excluent ne cohabitent pas (Allégé/Économe ; Persistant/Économe/Véloce). Aucune rune sur une commune ni sur une carte unique (rang 0).
A19: B. Probabilité de chaque rune, carte par carte (avant toute rune portée)
A20: Source : Colonnes « 1 tirage » : poids / somme des poids éligibles (formule). Colonnes « parmi 3 » : chance d'être dans l'offre de 3 runes de la fusion, énumération exacte des tirages pondérés sans remise (Python, valeur figée).
A21: Rang 1 = la carte vient de devenir peu commune (1re fusion) ; rang 2+ = rare ou mieux (Économe et Véloce deviennent éligibles). Les cartes de classe (uniques) ne reçoivent jamais de rune.
A22: Carte | B22: Rune | C22: Poids | D22: Élig. r1 | E22: P (1 tirage) r1 | F22: P (parmi 3) r1 | G22: Élig. r2+ | H22: P (1 tirage) r2+ | I22: P (parmi 3) r2+ | J22: Pourquoi inéligible (r1)
A23: Éveil (skill, coût 1) | B23: Brûlant | C23: 80 | D23: 0 | E23: =IF(D23=1,C23/SUMPRODUCT(C23:C33,D23:D33),0) -> 0 | F23: 0 | G23: 0 | H23: =IF(G23=1,C23/SUMPRODUCT(C23:C33,G23:G33),0) -> 0 | I23: 0 | J23: type de carte
A24: Éveil (skill, coût 1) | B24: Allégé | C24: 50 | D24: 1 | E24: =IF(D24=1,C24/SUMPRODUCT(C23:C33,D23:D33),0) -> 0.33333333 | F24: 1 | G24: 1 | H24: =IF(G24=1,C24/SUMPRODUCT(C23:C33,G23:G33),0) -> 0.2 | I24: 0.70884788
A25: Éveil (skill, coût 1) | B25: Économe | C25: 40 | D25: 0 | E25: =IF(D25=1,C25/SUMPRODUCT(C23:C33,D23:D33),0) -> 0 | F25: 0 | G25: 1 | H25: =IF(G25=1,C25/SUMPRODUCT(C23:C33,G23:G33),0) -> 0.16 | I25: 0.61296575 | J25: rang 2 requis
A26: Éveil (skill, coût 1) | B26: Persistant | C26: 30 | D26: 0 | E26: =IF(D26=1,C26/SUMPRODUCT(C23:C33,D23:D33),0) -> 0 | F26: 0 | G26: 0 | H26: =IF(G26=1,C26/SUMPRODUCT(C23:C33,G23:G33),0) -> 0 | I26: 0 | J26: pas d'Épuisement
A27: Éveil (skill, coût 1) | B27: Congelant | C27: 80 | D27: 0 | E27: =IF(D27=1,C27/SUMPRODUCT(C23:C33,D23:D33),0) -> 0 | F27: 0 | G27: 0 | H27: =IF(G27=1,C27/SUMPRODUCT(C23:C33,G23:G33),0) -> 0 | I27: 0 | J27: type de carte
A28: Éveil (skill, coût 1) | B28: Endurci | C28: 100 | D28: 1 | E28: =IF(D28=1,C28/SUMPRODUCT(C23:C33,D23:D33),0) -> 0.66666667 | F28: 1 | G28: 1 | H28: =IF(G28=1,C28/SUMPRODUCT(C23:C33,G23:G33),0) -> 0.4 | I28: 0.90344612
A29: Éveil (skill, coût 1) | B29: Précis | C29: 50 | D29: 0 | E29: =IF(D29=1,C29/SUMPRODUCT(C23:C33,D23:D33),0) -> 0 | F29: 0 | G29: 0 | H29: =IF(G29=1,C29/SUMPRODUCT(C23:C33,G23:G33),0) -> 0 | I29: 0 | J29: effet absent
A30: Éveil (skill, coût 1) | B30: Véloce | C30: 60 | D30: 0 | E30: =IF(D30=1,C30/SUMPRODUCT(C23:C33,D23:D33),0) -> 0 | F30: 0 | G30: 1 | H30: =IF(G30=1,C30/SUMPRODUCT(C23:C33,G23:G33),0) -> 0.24 | I30: 0.77474026 | J30: rang 2 requis
A31: Éveil (skill, coût 1) | B31: Tranchant | C31: 100 | D31: 0 | E31: =IF(D31=1,C31/SUMPRODUCT(C23:C33,D23:D33),0) -> 0 | F31: 0 | G31: 0 | H31: =IF(G31=1,C31/SUMPRODUCT(C23:C33,G23:G33),0) -> 0 | I31: 0 | J31: effet absent
A32: Éveil (skill, coût 1) | B32: Surchargé | C32: 80 | D32: 0 | E32: =IF(D32=1,C32/SUMPRODUCT(C23:C33,D23:D33),0) -> 0 | F32: 0 | G32: 0 | H32: =IF(G32=1,C32/SUMPRODUCT(C23:C33,G23:G33),0) -> 0 | I32: 0 | J32: type de carte
A33: Éveil (skill, coût 1) | B33: Spectral | C33: 50 | D33: 0 | E33: =IF(D33=1,C33/SUMPRODUCT(C23:C33,D23:D33),0) -> 0 | F33: 0 | G33: 0 | H33: =IF(G33=1,C33/SUMPRODUCT(C23:C33,G23:G33),0) -> 0 | I33: 0 | J33: effet absent
A34: Concentration (skill, coût 0) | B34: Brûlant | C34: 80 | D34: 0 | E34: =IF(D34=1,C34/SUMPRODUCT(C34:C44,D34:D44),0) -> 0 | F34: 0 | G34: 0 | H34: =IF(G34=1,C34/SUMPRODUCT(C34:C44,G34:G44),0) -> 0 | I34: 0 | J34: type de carte
A35: Concentration (skill, coût 0) | B35: Allégé | C35: 50 | D35: 0 | E35: =IF(D35=1,C35/SUMPRODUCT(C34:C44,D34:D44),0) -> 0 | F35: 0 | G35: 0 | H35: =IF(G35=1,C35/SUMPRODUCT(C34:C44,G34:G44),0) -> 0 | I35: 0 | J35: coût 0
A36: Concentration (skill, coût 0) | B36: Économe | C36: 40 | D36: 0 | E36: =IF(D36=1,C36/SUMPRODUCT(C34:C44,D34:D44),0) -> 0 | F36: 0 | G36: 0 | H36: =IF(G36=1,C36/SUMPRODUCT(C34:C44,G34:G44),0) -> 0 | I36: 0 | J36: coût 0
A37: Concentration (skill, coût 0) | B37: Persistant | C37: 30 | D37: 0 | E37: =IF(D37=1,C37/SUMPRODUCT(C34:C44,D34:D44),0) -> 0 | F37: 0 | G37: 0 | H37: =IF(G37=1,C37/SUMPRODUCT(C34:C44,G34:G44),0) -> 0 | I37: 0 | J37: pas d'Épuisement
A38: Concentration (skill, coût 0) | B38: Congelant | C38: 80 | D38: 0 | E38: =IF(D38=1,C38/SUMPRODUCT(C34:C44,D34:D44),0) -> 0 | F38: 0 | G38: 0 | H38: =IF(G38=1,C38/SUMPRODUCT(C34:C44,G34:G44),0) -> 0 | I38: 0 | J38: type de carte
A39: Concentration (skill, coût 0) | B39: Endurci | C39: 100 | D39: 0 | E39: =IF(D39=1,C39/SUMPRODUCT(C34:C44,D34:D44),0) -> 0 | F39: 0 | G39: 0 | H39: =IF(G39=1,C39/SUMPRODUCT(C34:C44,G34:G44),0) -> 0 | I39: 0 | J39: effet absent
A40: Concentration (skill, coût 0) | B40: Précis | C40: 50 | D40: 0 | E40: =IF(D40=1,C40/SUMPRODUCT(C34:C44,D34:D44),0) -> 0 | F40: 0 | G40: 0 | H40: =IF(G40=1,C40/SUMPRODUCT(C34:C44,G34:G44),0) -> 0 | I40: 0 | J40: effet absent
A41: Concentration (skill, coût 0) | B41: Véloce | C41: 60 | D41: 0 | E41: =IF(D41=1,C41/SUMPRODUCT(C34:C44,D34:D44),0) -> 0 | F41: 0 | G41: 1 | H41: =IF(G41=1,C41/SUMPRODUCT(C34:C44,G34:G44),0) -> 1 | I41: 1 | J41: rang 2 requis
A42: Concentration (skill, coût 0) | B42: Tranchant | C42: 100 | D42: 0 | E42: =IF(D42=1,C42/SUMPRODUCT(C34:C44,D34:D44),0) -> 0 | F42: 0 | G42: 0 | H42: =IF(G42=1,C42/SUMPRODUCT(C34:C44,G34:G44),0) -> 0 | I42: 0 | J42: effet absent
...

Sheet Critique
A1: Coup critique
A2: DamagePipeline.calculate (nextInt(100) < critChance effective + bonus de rune) ; HealEffectStrategy pour les soins ; EntityStats.critMultiplier = 1,5
A4: A. Sources de chance de critique (points de %)
A5: Source | B5: Valeur | C5: Portée | D5: Note
A6: Classe : Le Berserker | B6: 10 | C6: permanente | D6: class.json
A7: Classe : Le Mage | B7: 0 | C7: permanente | D7: class.json
A8: Classe : Le Paladin | B8: 0 | C8: permanente | D8: class.json
A9: Relique : Lentille de Focalisation (Rare) | B9: 15 | C9: toute la run | D9: startOfRun
A10: Relique : Porte-bonheur (Peu commune) | B10: 10 | C10: toute la run | D10: startOfRun
A11: Relique : Pièce de chance (Commune) | B11: 5 | C11: toute la run | D11: startOfRun
A12: Récompense Précision (par palier) | B12: 1 / 2 / 3 / 4 / 5 | C12: permanente | D12: commune → légendaire
A13: Rune Précis (par niveau, max 10) | B13: 5 | C13: les dégâts de la carte seulement | D13: jamais le soin
A14: Ennemi : Gobelin | B14: 10 | C14: ses attaques | D14: enemy.json
A15: Ennemi : Orc Furieux | B15: 15 | C15: ses attaques | D15: enemy.json
A16: Ennemi : Slime | B16: 5 | C16: ses attaques | D16: enemy.json
A17: Ennemi : Squelette | B17: 10 | C17: ses attaques | D17: enemy.json
A19: B. Multiplicateur et dégâts attendus
A20: Multiplicateur de base | B20: 1.5 | C20: EntityStats.critMultiplier ; Férocité ajoute +0,10 à +0,50
A21: Chance (pts) | B21: ×1,5 | C21: ×1,6 | D21: ×1,8 | E21: ×2,0 | F21: ×2,5 | G21: ×3,0 | H21: P(≥1 crit sur 3 attaques) | I21: P(≥1 crit sur 5 attaques)
A22: Multiplicateur → | B22: 1.5 | C22: 1.6 | D22: 1.8 | E22: 2 | F22: 2.5 | G22: 3
A23: 0 | B23: =1+MIN(1,A23/100)*($B$22-1) -> 1 | C23: =1+MIN(1,A23/100)*($C$22-1) -> 1 | D23: =1+MIN(1,A23/100)*($D$22-1) -> 1 | E23: =1+MIN(1,A23/100)*($E$22-1) -> 1 | F23: =1+MIN(1,A23/100)*($F$22-1) -> 1 | G23: =1+MIN(1,A23/100)*($G$22-1) -> 1 | H23: =1-(1-MIN(1,A23/100))^3 -> 0 | I23: =1-(1-MIN(1,A23/100))^5 -> 0
A24: 5 | B24: =1+MIN(1,A24/100)*($B$22-1) -> 1.025 | C24: =1+MIN(1,A24/100)*($C$22-1) -> 1.03 | D24: =1+MIN(1,A24/100)*($D$22-1) -> 1.04 | E24: =1+MIN(1,A24/100)*($E$22-1) -> 1.05 | F24: =1+MIN(1,A24/100)*($F$22-1) -> 1.075 | G24: =1+MIN(1,A24/100)*($G$22-1) -> 1.1 | H24: =1-(1-MIN(1,A24/100))^3 -> 0.142625 | I24: =1-(1-MIN(1,A24/100))^5 -> 0.22621906
A25: 10 | B25: =1+MIN(1,A25/100)*($B$22-1) -> 1.05 | C25: =1+MIN(1,A25/100)*($C$22-1) -> 1.06 | D25: =1+MIN(1,A25/100)*($D$22-1) -> 1.08 | E25: =1+MIN(1,A25/100)*($E$22-1) -> 1.1 | F25: =1+MIN(1,A25/100)*($F$22-1) -> 1.15 | G25: =1+MIN(1,A25/100)*($G$22-1) -> 1.2 | H25: =1-(1-MIN(1,A25/100))^3 -> 0.271 | I25: =1-(1-MIN(1,A25/100))^5 -> 0.40951
A26: 15 | B26: =1+MIN(1,A26/100)*($B$22-1) -> 1.075 | C26: =1+MIN(1,A26/100)*($C$22-1) -> 1.09 | D26: =1+MIN(1,A26/100)*($D$22-1) -> 1.12 | E26: =1+MIN(1,A26/100)*($E$22-1) -> 1.15 | F26: =1+MIN(1,A26/100)*($F$22-1) -> 1.225 | G26: =1+MIN(1,A26/100)*($G$22-1) -> 1.3 | H26: =1-(1-MIN(1,A26/100))^3 -> 0.385875 | I26: =1-(1-MIN(1,A26/100))^5 -> 0.55629469
A27: 20 | B27: =1+MIN(1,A27/100)*($B$22-1) -> 1.1 | C27: =1+MIN(1,A27/100)*($C$22-1) -> 1.12 | D27: =1+MIN(1,A27/100)*($D$22-1) -> 1.16 | E27: =1+MIN(1,A27/100)*($E$22-1) -> 1.2 | F27: =1+MIN(1,A27/100)*($F$22-1) -> 1.3 | G27: =1+MIN(1,A27/100)*($G$22-1) -> 1.4 | H27: =1-(1-MIN(1,A27/100))^3 -> 0.488 | I27: =1-(1-MIN(1,A27/100))^5 -> 0.67232
A28: 25 | B28: =1+MIN(1,A28/100)*($B$22-1) -> 1.125 | C28: =1+MIN(1,A28/100)*($C$22-1) -> 1.15 | D28: =1+MIN(1,A28/100)*($D$22-1) -> 1.2 | E28: =1+MIN(1,A28/100)*($E$22-1) -> 1.25 | F28: =1+MIN(1,A28/100)*($F$22-1) -> 1.375 | G28: =1+MIN(1,A28/100)*($G$22-1) -> 1.5 | H28: =1-(1-MIN(1,A28/100))^3 -> 0.578125 | I28: =1-(1-MIN(1,A28/100))^5 -> 0.76269531
A29: 30 | B29: =1+MIN(1,A29/100)*($B$22-1) -> 1.15 | C29: =1+MIN(1,A29/100)*($C$22-1) -> 1.18 | D29: =1+MIN(1,A29/100)*($D$22-1) -> 1.24 | E29: =1+MIN(1,A29/100)*($E$22-1) -> 1.3 | F29: =1+MIN(1,A29/100)*($F$22-1) -> 1.45 | G29: =1+MIN(1,A29/100)*($G$22-1) -> 1.6 | H29: =1-(1-MIN(1,A29/100))^3 -> 0.657 | I29: =1-(1-MIN(1,A29/100))^5 -> 0.83193
A30: 35 | B30: =1+MIN(1,A30/100)*($B$22-1) -> 1.175 | C30: =1+MIN(1,A30/100)*($C$22-1) -> 1.21 | D30: =1+MIN(1,A30/100)*($D$22-1) -> 1.28 | E30: =1+MIN(1,A30/100)*($E$22-1) -> 1.35 | F30: =1+MIN(1,A30/100)*($F$22-1) -> 1.525 | G30: =1+MIN(1,A30/100)*($G$22-1) -> 1.7 | H30: =1-(1-MIN(1,A30/100))^3 -> 0.725375 | I30: =1-(1-MIN(1,A30/100))^5 -> 0.88397094
A31: 40 | B31: =1+MIN(1,A31/100)*($B$22-1) -> 1.2 | C31: =1+MIN(1,A31/100)*($C$22-1) -> 1.24 | D31: =1+MIN(1,A31/100)*($D$22-1) -> 1.32 | E31: =1+MIN(1,A31/100)*($E$22-1) -> 1.4 | F31: =1+MIN(1,A31/100)*($F$22-1) -> 1.6 | G31: =1+MIN(1,A31/100)*($G$22-1) -> 1.8 | H31: =1-(1-MIN(1,A31/100))^3 -> 0.784 | I31: =1-(1-MIN(1,A31/100))^5 -> 0.92224
A32: 45 | B32: =1+MIN(1,A32/100)*($B$22-1) -> 1.225 | C32: =1+MIN(1,A32/100)*($C$22-1) -> 1.27 | D32: =1+MIN(1,A32/100)*($D$22-1) -> 1.36 | E32: =1+MIN(1,A32/100)*($E$22-1) -> 1.45 | F32: =1+MIN(1,A32/100)*($F$22-1) -> 1.675 | G32: =1+MIN(1,A32/100)*($G$22-1) -> 1.9 | H32: =1-(1-MIN(1,A32/100))^3 -> 0.833625 | I32: =1-(1-MIN(1,A32/100))^5 -> 0.94967156
A33: 50 | B33: =1+MIN(1,A33/100)*($B$22-1) -> 1.25 | C33: =1+MIN(1,A33/100)*($C$22-1) -> 1.3 | D33: =1+MIN(1,A33/100)*($D$22-1) -> 1.4 | E33: =1+MIN(1,A33/100)*($E$22-1) -> 1.5 | F33: =1+MIN(1,A33/100)*($F$22-1) -> 1.75 | G33: =1+MIN(1,A33/100)*($G$22-1) -> 2 | H33: =1-(1-MIN(1,A33/100))^3 -> 0.875 | I33: =1-(1-MIN(1,A33/100))^5 -> 0.96875
A34: 55 | B34: =1+MIN(1,A34/100)*($B$22-1) -> 1.275 | C34: =1+MIN(1,A34/100)*($C$22-1) -> 1.33 | D34: =1+MIN(1,A34/100)*($D$22-1) -> 1.44 | E34: =1+MIN(1,A34/100)*($E$22-1) -> 1.55 | F34: =1+MIN(1,A34/100)*($F$22-1) -> 1.825 | G34: =1+MIN(1,A34/100)*($G$22-1) -> 2.1 | H34: =1-(1-MIN(1,A34/100))^3 -> 0.908875 | I34: =1-(1-MIN(1,A34/100))^5 -> 0.98154719
... A43: 100 | B43: =1+MIN(1,A43/100)*($B$22-1) -> 1.5 | C43: =1+MIN(1,A43/100)*($C$22-1) -> 1.6 | D43: =1+MIN(1,A43/100)*($D$22-1) -> 1.8 | E43: =1+MIN(1,A43/100)*($E$22-1) -> 2 | F43: =1+MIN(1,A43/100)*($F$22-1) -> 2.5 | G43: =1+MIN(1,A43/100)*($G$22-1) -> 3 | H43: =1-(1-MIN(1,A43/100))^3 -> 1 | I43: =1-(1-MIN(1,A43/100))^5 -> 1
A44: Facteur de dégâts attendu = 1 + p × (m − 1). Une chance ≥ 100 critique toujours.
A46: C. Exemple de cumul (Berserker)
A47: Classe Berserker | B47: 10
A48: Porte-bonheur | B48: 10
A49: Lentille de Focalisation | B49: 15
A50: Précision légendaire | B50: 5
A51: Rune Précis niveau 3 (sur cette carte) | B51: 15
...

Sheet Rencontres
A1: Composition d'un combat
A2: EncounterSystem.generateEnemiesForLevel (lib/game/systems/encounter_system.dart) — le seul tirage : un candidat uniforme parmi ceux qui tiennent dans le budget restant
A4: A. Tiers débloqués et nombre maximal d'ennemis, par acte
A5: Source : getUnlockedTier = min(3, 1 + (acte−1) ÷ 5) ; max ennemis : normal 1 + (acte−1), élite 1 + (acte−1) ÷ 2, boss 1 + (acte−1) ÷ 5 ; 5 ennemis actifs au plus, le reste en réserve
A6: Déblocage de tier tous les | B6: 5 | C6: actes
A7: Acte | B7: Tier max | C7: Ennemis éligibles | D7: Max normal | E7: Max élite | F7: Max boss
A8: 1 | B8: =MIN(3,1+INT((A8-1)/$B$6)) -> 1 | C8: =IF(B8=1,"Gobelin, Slime",IF(B8=2,"Gobelin, Slime, Squelette","Gobelin, Orc Furieux, Slime, Squelette")) -> Gobelin, Slime | D8: =1+(A8-1) -> 1 | E8: =1+INT((A8-1)/2) -> 1 | F8: =1+INT((A8-1)/5) -> 1
A9: 2 | B9: =MIN(3,1+INT((A9-1)/$B$6)) -> 1 | C9: =IF(B9=1,"Gobelin, Slime",IF(B9=2,"Gobelin, Slime, Squelette","Gobelin, Orc Furieux, Slime, Squelette")) -> Gobelin, Slime | D9: =1+(A9-1) -> 2 | E9: =1+INT((A9-1)/2) -> 1 | F9: =1+INT((A9-1)/5) -> 1
A10: 3 | B10: =MIN(3,1+INT((A10-1)/$B$6)) -> 1 | C10: =IF(B10=1,"Gobelin, Slime",IF(B10=2,"Gobelin, Slime, Squelette","Gobelin, Orc Furieux, Slime, Squelette")) -> Gobelin, Slime | D10: =1+(A10-1) -> 3 | E10: =1+INT((A10-1)/2) -> 2 | F10: =1+INT((A10-1)/5) -> 1
A11: 4 | B11: =MIN(3,1+INT((A11-1)/$B$6)) -> 1 | C11: =IF(B11=1,"Gobelin, Slime",IF(B11=2,"Gobelin, Slime, Squelette","Gobelin, Orc Furieux, Slime, Squelette")) -> Gobelin, Slime | D11: =1+(A11-1) -> 4 | E11: =1+INT((A11-1)/2) -> 2 | F11: =1+INT((A11-1)/5) -> 1
A12: 5 | B12: =MIN(3,1+INT((A12-1)/$B$6)) -> 1 | C12: =IF(B12=1,"Gobelin, Slime",IF(B12=2,"Gobelin, Slime, Squelette","Gobelin, Orc Furieux, Slime, Squelette")) -> Gobelin, Slime | D12: =1+(A12-1) -> 5 | E12: =1+INT((A12-1)/2) -> 3 | F12: =1+INT((A12-1)/5) -> 1
A13: 6 | B13: =MIN(3,1+INT((A13-1)/$B$6)) -> 2 | C13: =IF(B13=1,"Gobelin, Slime",IF(B13=2,"Gobelin, Slime, Squelette","Gobelin, Orc Furieux, Slime, Squelette")) -> Gobelin, Slime, Squelette | D13: =1+(A13-1) -> 6 | E13: =1+INT((A13-1)/2) -> 3 | F13: =1+INT((A13-1)/5) -> 2
A14: 7 | B14: =MIN(3,1+INT((A14-1)/$B$6)) -> 2 | C14: =IF(B14=1,"Gobelin, Slime",IF(B14=2,"Gobelin, Slime, Squelette","Gobelin, Orc Furieux, Slime, Squelette")) -> Gobelin, Slime, Squelette | D14: =1+(A14-1) -> 7 | E14: =1+INT((A14-1)/2) -> 4 | F14: =1+INT((A14-1)/5) -> 2
A15: 8 | B15: =MIN(3,1+INT((A15-1)/$B$6)) -> 2 | C15: =IF(B15=1,"Gobelin, Slime",IF(B15=2,"Gobelin, Slime, Squelette","Gobelin, Orc Furieux, Slime, Squelette")) -> Gobelin, Slime, Squelette | D15: =1+(A15-1) -> 8 | E15: =1+INT((A15-1)/2) -> 4 | F15: =1+INT((A15-1)/5) -> 2
A16: 9 | B16: =MIN(3,1+INT((A16-1)/$B$6)) -> 2 | C16: =IF(B16=1,"Gobelin, Slime",IF(B16=2,"Gobelin, Slime, Squelette","Gobelin, Orc Furieux, Slime, Squelette")) -> Gobelin, Slime, Squelette | D16: =1+(A16-1) -> 9 | E16: =1+INT((A16-1)/2) -> 5 | F16: =1+INT((A16-1)/5) -> 2
A17: 10 | B17: =MIN(3,1+INT((A17-1)/$B$6)) -> 2 | C17: =IF(B17=1,"Gobelin, Slime",IF(B17=2,"Gobelin, Slime, Squelette","Gobelin, Orc Furieux, Slime, Squelette")) -> Gobelin, Slime, Squelette | D17: =1+(A17-1) -> 10 | E17: =1+INT((A17-1)/2) -> 5 | F17: =1+INT((A17-1)/5) -> 2
A18: 11 | B18: =MIN(3,1+INT((A18-1)/$B$6)) -> 3 | C18: =IF(B18=1,"Gobelin, Slime",IF(B18=2,"Gobelin, Slime, Squelette","Gobelin, Orc Furieux, Slime, Squelette")) -> Gobelin, Orc Furieux, Slime, Squelette | D18: =1+(A18-1) -> 11 | E18: =1+INT((A18-1)/2) -> 6 | F18: =1+INT((A18-1)/5) -> 3
A19: 12 | B19: =MIN(3,1+INT((A19-1)/$B$6)) -> 3 | C19: =IF(B19=1,"Gobelin, Slime",IF(B19=2,"Gobelin, Slime, Squelette","Gobelin, Orc Furieux, Slime, Squelette")) -> Gobelin, Orc Furieux, Slime, Squelette | D19: =1+(A19-1) -> 12 | E19: =1+INT((A19-1)/2) -> 6 | F19: =1+INT((A19-1)/5) -> 3
... A27: 20 | B27: =MIN(3,1+INT((A27-1)/$B$6)) -> 3 | C27: =IF(B27=1,"Gobelin, Slime",IF(B27=2,"Gobelin, Slime, Squelette","Gobelin, Orc Furieux, Slime, Squelette")) -> Gobelin, Orc Furieux, Slime, Squelette | D27: =1+(A27-1) -> 20 | E27: =1+INT((A27-1)/2) -> 10 | F27: =1+INT((A27-1)/5) -> 4
A29: B. Intentions d'un ennemi
A30: Source : CombatController.rollIntent : si l'ennemi a une liste intents, cycle déterministe ; sinon attaque 60 %, défense 25 % (5 + nextInt(6) armure), buff 15 % (+2 Puissance)
A31: Ennemi | B31: Pattern (cycle) | C31: Tirage ?
A32: Gobelin | B32: attack 5 | C32: non — cycle fixe
A33: Orc Furieux | B33: attack 8 → buff 2 → attack 12 | C33: non — cycle fixe
A34: Slime | B34: attack 4 | C34: non — cycle fixe
A35: Squelette | B35: attack 8 → attack 10 | C35: non — cycle fixe
A36: Repli (ennemi sans pattern) | B36: Probabilité | C36: Valeur
A37: Attaque | B37: 0.6 | C37: baseDamage
A38: Défense | B38: 0.25 | C38: 5 à 10 armure, uniforme (1/6 chacun), 7,5 en moyenne
A39: Buff | B39: 0.15 | C39: +2 Puissance
A40: Aucun des quatre ennemis livrés n'utilise le repli : leurs intentions sont prévisibles.
A42: C. Calculateur : qui peut sortir, et avec quelle chance au 1er tirage
A43: Source : calculateBudget, getEnemyLevel, getHpMultiplier, getDamageMultiplier, calculateCombatRating — mêmes formules que l'onglet « Calculateur de combat » du second classeur
A44: Acte | B44: 1
A45: Niveau du joueur | B45: 1
A46: PV max | B46: 100
A47: Puissance permanente | B47: 0
A48: Mana max | B48: 3
A49: Reliques | B49: 0
A50: Somme des rangs de fusion du deck | B50: 0
...

Sheet Événements
A1: Événements narratifs
A2: EventController.initializeEvent : events[nextInt(events.length)] — uniforme
A4: A. Les événements et leur chance par nœud Événement
A5: Événements livrés | B5: 7 | C5: assets/data/events/*.json
A6: Événement | B6: id | C6: P(ce nœud) | D6: Choix | F6: Actions (value) et conditions
A7: Le Feu de Camp Abandonné | B7: abandoned_camp | C7: =1/$B$5 -> 0.14285714 | D7: Fouiller les sacs restants (-10 PV, +1 Relique) | F7: take_damage 10, gain_relic 1
D8: Se reposer près du feu (+15 PV) | F8: heal 15
D9: Consommer les provisions abandonnées (-25 Or, +30 PV) | F9: spend_gold 25, heal 30
A10: La Fontaine Bénie | B10: blessed_fountain | C10: =1/$B$5 -> 0.14285714 | D10: Boire l'eau bénie (+25 PV) | F10: heal 25
D11: Purifier son esprit (-12 PV Max, +1 Puissance) | F11: gain_max_hp -12, gain_might 1
D12: Jeter une pièce dans la fontaine (-20 Or, +8 PV Max) | F12: spend_gold 20, gain_max_hp 8
A13: Le Tombeau Oublié | B13: forgotten_tomb | C13: =1/$B$5 -> 0.14285714 | D13: Piller le sarcophage (+100 Or, -18 PV) | F13: gain_gold 100, take_damage 18
D14: Inspecter les gravures murales (+10 PV Max) | F14: gain_max_hp 10
D15: Respecter le repos des morts (+15 Or) | F15: gain_gold 15
A16: Le Marchand Fugitif | B16: goblin_merchant | C16: =1/$B$5 -> 0.14285714 | D16: Acheter une relique mystérieuse (-40 Or, +1 Relique) | F16: spend_gold 40, gain_relic 1
D17: Voler le gobelin (+50 Or, -12 PV) | F17: gain_gold 50, take_damage 12
D18: L'aider à se cacher (-15 PV, +1 Relique) | F18: take_damage 15, gain_relic 1
A19: L'Autel Mystérieux | B19: mysterious_altar | C19: =1/$B$5 -> 0.14285714 | D19: Sacrifier votre sang (-15 PV, +1 Puissance) | F19: take_damage 15, gain_might 1
D20: Faire une offrande d'or (-50 Or, +10 PV Max) | F20: spend_gold 50, gain_max_hp 10
D21: Prier et partir (Rien) | F21: rien
A22: Le Colporteur | B22: relic_peddler | C22: =1/$B$5 -> 0.14285714 | D22: Vendre votre relique la plus faible (+40 à +200 Or selon sa rareté) | F22: trade_relic 40
D23: L'échanger contre des remèdes (+20 % des PV max, si vos PV sont sous la moitié) | F23: trade_relic 0, heal_percent 20 [PV < 50 % des PV max]
D24: Passer votre chemin (Rien) | F24: rien
A25: Le Rémouleur | B25: wandering_grinder | C25: =1/$B$5 -> 0.14285714 | D25: Lui confier une rune (-10 % des PV max, +1 niveau de rune) | F25: lose_hp_percent 10, sharpen_rune 1
D26: Passer votre chemin (Rien) | F26: rien
A27: Conditions implicites (EventChoice.isSelectable) : take_damage et lose_hp_percent exigent PV > coût ; spend_gold exige l'or ; gain_max_hp négatif exige PV max > perte ; trade_relic exige une relique ; sharpen_rune exige une rune affûtable.
A29: B. Chances cumulées
A30: Visites de nœuds Événement (n) | B30: P(un événement précis au moins 1 fois) | C30: P(jamais le même deux fois) | D30: P(une relique proposée au moins 1 fois)
A31: 1 | B31: =1-(1-1/$B$5)^A31 -> 0.14285714 | C31: =IF(A31>$B$5,0,FACT($B$5)/FACT($B$5-A31)/$B$5^A31) -> 1 | D31: =1-(1-2/$B$5)^A31 -> 0.28571429
A32: 2 | B32: =1-(1-1/$B$5)^A32 -> 0.26530612 | C32: =IF(A32>$B$5,0,FACT($B$5)/FACT($B$5-A32)/$B$5^A32) -> 0.85714286 | D32: =1-(1-2/$B$5)^A32 -> 0.48979592
A33: 3 | B33: =1-(1-1/$B$5)^A33 -> 0.37026239 | C33: =IF(A33>$B$5,0,FACT($B$5)/FACT($B$5-A33)/$B$5^A33) -> 0.6122449 | D33: =1-(1-2/$B$5)^A33 -> 0.63556851
A34: 4 | B34: =1-(1-1/$B$5)^A34 -> 0.46022491 | C34: =IF(A34>$B$5,0,FACT($B$5)/FACT($B$5-A34)/$B$5^A34) -> 0.34985423 | D34: =1-(1-2/$B$5)^A34 -> 0.7396918
A35: 5 | B35: =1-(1-1/$B$5)^A35 -> 0.53733563 | C35: =IF(A35>$B$5,0,FACT($B$5)/FACT($B$5-A35)/$B$5^A35) -> 0.14993753 | D35: =1-(1-2/$B$5)^A35 -> 0.81406557
A36: 6 | B36: =1-(1-1/$B$5)^A36 -> 0.60343054 | C36: =IF(A36>$B$5,0,FACT($B$5)/FACT($B$5-A36)/$B$5^A36) -> 0.042839293 | D36: =1-(1-2/$B$5)^A36 -> 0.86718969
A37: 7 | B37: =1-(1-1/$B$5)^A37 -> 0.66008332 | C37: =IF(A37>$B$5,0,FACT($B$5)/FACT($B$5-A37)/$B$5^A37) -> 0.006119899 | D37: =1-(1-2/$B$5)^A37 -> 0.90513549
A38: 8 | B38: =1-(1-1/$B$5)^A38 -> 0.70864285 | C38: =IF(A38>$B$5,0,FACT($B$5)/FACT($B$5-A38)/$B$5^A38) -> 0 | D38: =1-(1-2/$B$5)^A38 -> 0.93223964
A39: 9 | B39: =1-(1-1/$B$5)^A39 -> 0.7502653 | C39: =IF(A39>$B$5,0,FACT($B$5)/FACT($B$5-A39)/$B$5^A39) -> 0 | D39: =1-(1-2/$B$5)^A39 -> 0.95159974
A40: 10 | B40: =1-(1-1/$B$5)^A40 -> 0.78594168 | C40: =IF(A40>$B$5,0,FACT($B$5)/FACT($B$5-A40)/$B$5^A40) -> 0 | D40: =1-(1-2/$B$5)^A40 -> 0.96542839
A41: 11 | B41: =1-(1-1/$B$5)^A41 -> 0.81652144 | C41: =IF(A41>$B$5,0,FACT($B$5)/FACT($B$5-A41)/$B$5^A41) -> 0 | D41: =1-(1-2/$B$5)^A41 -> 0.97530599
A42: 12 | B42: =1-(1-1/$B$5)^A42 -> 0.84273267 | C42: =IF(A42>$B$5,0,FACT($B$5)/FACT($B$5-A42)/$B$5^A42) -> 0 | D42: =1-(1-2/$B$5)^A42 -> 0.98236142
...

Sheet Pioche
A1: Pioche et main d'ouverture
A2: DeckNotifier.startCombat / drawCards (lib/game/controllers/deck_controller.dart) : mélange uniforme, remélange à sec, arrêt net à la main max
A4: A. Paramètres
A5: Cartes piochées par tour (cardsPerTurn) | B5: 5 | C5: +1 par Besace de l'Érudit
A6: Main maximale | B6: 10 | C6: GameConstants.startingMaxHandSize
A7: Taille du deck N | B7: 7 | C7: 7 au départ : 2 cartes de classe + 5 choisies
A8: Copies d'une carte donnée k | B8: 1
A10: B. P(au moins une des k copies dans la main d'ouverture), loi hypergéométrique
